Workbook

Sheet Threat Scenarios
A1: ID | B1: Name | C1: Assets | D1: To Be Assessed | E1: Category
A2: TS-001 | B2: Spoofing of AI Controller Module: rogue ECU impersonates the controller and sends forged ACC decisions to the Actuation Module | C2: AI Controller Module | D2: =TRUE() -> TRUE | E2: Spoofing
A3: TS-002 | B3: Tampering with AI Controller Module: manipulation of AI model weights, parameters or software (model poisoning, backdoor, malicious update) | C3: AI Controller Module | D3: =TRUE() -> TRUE | E3: Tampering
A4: TS-003 | B4: Repudiation of AI Controller Module: no tamper-proof log to prove which ACC decision was taken and on which inputs | C4: AI Controller Module | D4: =TRUE() -> TRUE | E4: Repudiation
A5: TS-004 | B5: Information disclosure of AI Controller Module: extraction of the proprietary AI model (model stealing), enabling offline design of adversarial inputs | C5: AI Controller Module | D5: =TRUE() -> TRUE | E5: Information Disclosure
A6: TS-005 | B6: Denial of service on AI Controller Module: resource exhaustion or crafted inputs (sponge examples) delay or block ACC decisions | C6: AI Controller Module | D6: =TRUE() -> TRUE | E6: Denial of Service
A7: TS-006 | B7: Elevation of privilege on AI Controller Module: software vulnerability exploited to gain privileged execution and full control of ACC decisions | C7: AI Controller Module | D7: =TRUE() -> TRUE | E7: Elevation of Privilege
A8: TS-007 | B8: Spoofing of Perception Module: impersonation of the module to deliver fabricated environment data to the AI Controller Module | C8: Perception Module | D8: =TRUE() -> TRUE | E8: Spoofing
A9: TS-008 | B9: Tampering with Perception Module: manipulation of sensor fusion software or calibration parameters falsifies lead vehicle distance and speed | C9: Perception Module | D9: =TRUE() -> TRUE | E9: Tampering
A10: TS-009 | B10: Repudiation of Perception Module: denial of having produced specific environment data | C10: Perception Module | D10: =FALSE() -> FALSE | E10: Repudiation
A11: TS-010 | B11: Information disclosure of Perception Module: leakage of processed environment data (road users, location) or proprietary fusion algorithms | C11: Perception Module | D11: =TRUE() -> TRUE | E11: Information Disclosure
A12: TS-011 | B12: Denial of service on Perception Module: flooding with excessive or malformed sensor data prevents real-time object list output | C12: Perception Module | D12: =TRUE() -> TRUE | E12: Denial of Service
A13: TS-012 | B13: Elevation of privilege on Perception Module: exploited software gives the attacker control over environment data sent to the AI Controller Module | C13: Perception Module | D13: =TRUE() -> TRUE | E13: Elevation of Privilege
A14: TS-013 | B14: Spoofing of Actuation Module: rogue node impersonates the module and issues forged commands to Brake, Throttle and AEB | C14: Actuation Module | D14: =TRUE() -> TRUE | E14: Spoofing
A15: TS-014 | B15: Tampering with Actuation Module: modified software or limits (max acceleration/deceleration, command mapping) cause unintended braking or acceleration | C15: Actuation Module | D15: =TRUE() -> TRUE | E15: Tampering
A16: TS-015 | B16: Repudiation of Actuation Module: denial of having executed specific brake or throttle commands | C16: Actuation Module | D16: =FALSE() -> FALSE | E16: Repudiation
A17: TS-016 | B17: Information disclosure of Actuation Module: leakage of actuation parameters and calibration data | C17: Actuation Module | D17: =FALSE() -> FALSE | E17: Information Disclosure
A18: TS-017 | B18: Denial of service on Actuation Module: crash or overload prevents execution of ACC commands (no deceleration when required) | C18: Actuation Module | D18: =TRUE() -> TRUE | E18: Denial of Service
A19: TS-018 | B19: Elevation of privilege on Actuation Module: exploited software gives the attacker direct control of brake, throttle and AEB commands | C19: Actuation Module | D19: =TRUE() -> TRUE | E19: Elevation of Privilege
A20: TS-019 | B20: Spoofing of Camera: adversarial patches or projected/displayed fake objects and lane markings deceive the AI-based object detection | C20: Camera | D20: =TRUE() -> TRUE | E20: Spoofing
A21: TS-020 | B21: Tampering with Camera: physical misalignment, lens manipulation or modified firmware/calibration degrade object detection | C21: Camera | D21: =TRUE() -> TRUE | E21: Tampering
A22: TS-021 | B22: Repudiation of Camera: denial of having captured specific image data | C22: Camera | D22: =FALSE() -> FALSE | E22: Repudiation
A23: TS-022 | B23: Information disclosure of Camera: extraction of captured images from the sensor unit | C23: Camera | D23: =FALSE() -> FALSE | E23: Information Disclosure
A24: TS-023 | B24: Denial of service on Camera: blinding with strong light or laser, or covering the lens, removes visual input | C24: Camera | D24: =TRUE() -> TRUE | E24: Denial of Service
A25: TS-024 | B25: Elevation of privilege on Camera: exploitation of sensor firmware to gain privileged access | C25: Camera | D25: =FALSE() -> FALSE | E25: Elevation of Privilege
A26: TS-025 | B26: Spoofing of Radar: injected or replayed radar signals create ghost targets or falsify distance/relative speed (phantom braking) | C26: Radar | D26: =TRUE() -> TRUE | E26: Spoofing
A27: TS-026 | B27: Tampering with Radar: physical misalignment of the sensor mount, radome obstruction or modified firmware/calibration | C27: Radar | D27: =TRUE() -> TRUE | E27: Tampering
A28: TS-027 | B28: Repudiation of Radar: denial of having produced specific target data | C28: Radar | D28: =FALSE() -> FALSE | E28: Repudiation
A29: TS-028 | B29: Information disclosure of Radar: extraction of radar target data from the sensor unit | C29: Radar | D29: =FALSE() -> FALSE | E29: Information Disclosure
A30: TS-029 | B30: Denial of service on Radar: RF jamming in the radar frequency band prevents target detection | C30: Radar | D30: =TRUE() -> TRUE | E30: Denial of Service
A31: TS-030 | B31: Elevation of privilege on Radar: exploitation of sensor firmware to gain privileged access | C31: Radar | D31: =FALSE() -> FALSE | E31: Elevation of Privilege
A32: TS-031 | B32: Spoofing of LIDAR: injected laser pulses create phantom objects or hide real obstacles in the point cloud | C32: LIDAR | D32: =TRUE() -> TRUE | E32: Spoofing
A33: TS-032 | B33: Tampering with LIDAR: physical obstruction or misalignment, modified firmware/calibration distort the point cloud | C33: LIDAR | D33: =TRUE() -> TRUE | E33: Tampering
A34: TS-033 | B34: Repudiation of LIDAR: denial of having produced specific point cloud data | C34: LIDAR | D34: =FALSE() -> FALSE | E34: Repudiation
A35: TS-034 | B35: Information disclosure of LIDAR: extraction of point cloud data from the sensor unit | C35: LIDAR | D35: =FALSE() -> FALSE | E35: Information Disclosure
A36: TS-035 | B36: Denial of service on LIDAR: saturation with high-intensity laser light blinds the sensor | C36: LIDAR | D36: =TRUE() -> TRUE | E36: Denial of Service
A37: TS-036 | B37: Elevation of privilege on LIDAR: exploitation of sensor firmware to gain privileged access | C37: LIDAR | D37: =FALSE() -> FALSE | E37: Elevation of Privilege
A38: TS-037 | B38: Spoofing of OBU: forged V2X messages or impersonated road users/RSUs (Sybil attack) report false traffic situations | C38: OBU | D38: =TRUE() -> TRUE | E38: Spoofing
A39: TS-038 | B39: Tampering with OBU: modified firmware, software or certificate/key store via wireless or physical interfaces | C39: OBU | D39: =TRUE() -> TRUE | E39: Tampering
A40: TS-039 | B40: Repudiation of OBU: sender of malicious V2X messages cannot be identified due to missing signatures or logging | C40: OBU | D40: =TRUE() -> TRUE | E40: Repudiation
...

Sheet Summary
A1: TARA Summary - AI engine result (formulas read from 'Threat Scenarios')
A3: A. Threat scenarios per STRIDE category
A4: Category | B4: Total | C4: To Be Assessed = TRUE | D4: To Be Assessed = FALSE
A5: Spoofing | B5: =COUNTIFS('Threat Scenarios'!$E$2:$E$88,$A5) -> 10 | C5: =COUNTIFS('Threat Scenarios'!$E$2:$E$88,$A5,'Threat Scenarios'!$D$2:$D$88,TRUE()) -> 7 | D5: =B5-C5 -> 3
A6: Tampering | B6: =COUNTIFS('Threat Scenarios'!$E$2:$E$88,$A6) -> 19 | C6: =COUNTIFS('Threat Scenarios'!$E$2:$E$88,$A6,'Threat Scenarios'!$D$2:$D$88,TRUE()) -> 19 | D6: =B6-C6 -> 0
A7: Repudiation | B7: =COUNTIFS('Threat Scenarios'!$E$2:$E$88,$A7) -> 10 | C7: =COUNTIFS('Threat Scenarios'!$E$2:$E$88,$A7,'Threat Scenarios'!$D$2:$D$88,TRUE()) -> 2 | D7: =B7-C7 -> 8
A8: Information Disclosure | B8: =COUNTIFS('Threat Scenarios'!$E$2:$E$88,$A8) -> 19 | C8: =COUNTIFS('Threat Scenarios'!$E$2:$E$88,$A8,'Threat Scenarios'!$D$2:$D$88,TRUE()) -> 4 | D8: =B8-C8 -> 15
A9: Denial of Service | B9: =COUNTIFS('Threat Scenarios'!$E$2:$E$88,$A9) -> 19 | C9: =COUNTIFS('Threat Scenarios'!$E$2:$E$88,$A9,'Threat Scenarios'!$D$2:$D$88,TRUE()) -> 19 | D9: =B9-C9 -> 0
A10: Elevation of Privilege | B10: =COUNTIFS('Threat Scenarios'!$E$2:$E$88,$A10) -> 10 | C10: =COUNTIFS('Threat Scenarios'!$E$2:$E$88,$A10,'Threat Scenarios'!$D$2:$D$88,TRUE()) -> 4 | D10: =B10-C10 -> 6
A11: Total | B11: =SUM(B5:B10) -> 87 | C11: =SUM(C5:C10) -> 55 | D11: =SUM(D5:D10) -> 32
A14: B. Asset x STRIDE matrix (TRUE = to be assessed, FALSE = identified but not assessed, n/a = category not applied to this asset type)
A15: Asset | B15: Spoofing | C15: Tampering | D15: Repudiation | E15: Information Disclosure | F15: Denial of Service | G15: Elevation of Privilege | H15: Assessed count
A16: AI Controller Module | B16: =IF(COUNTIFS('Threat Scenarios'!$C$2:$C$88,$A16,'Threat Scenarios'!$E$2:$E$88,B$15)=0,"n/a",IF(COUNTIFS('Threat Scenarios'!$C$2:$C$88,$A16,'Threat Scenarios'!$E$2:$E$88,B$15,'Threat Scenarios'!$D$2:$D$88,TRUE())>0,"TRUE","FALSE")) -> TRUE | C16: =IF(COUNTIFS('Threat Scenarios'!$C$2:$C$88,$A16,'Threat Scenarios'!$E$2:$E$88,C$15)=0,"n/a",IF(COUNTIFS('Threat Scenarios'!$C$2:$C$88,$A16,'Threat Scenarios'!$E$2:$E$88,C$15,'Threat Scenarios'!$D$2:$D$88,TRUE())>0,"TRUE","FALSE")) -> TRUE | D16: =IF(COUNTIFS('Threat Scenarios'!$C$2:$C$88,$A16,'Threat Scenarios'!$E$2:$E$88,D$15)=0,"n/a",IF(COUNTIFS('Threat Scenarios'!$C$2:$C$88,$A16,'Threat Scenarios'!$E$2:$E$88,D$15,'Threat Scenarios'!$D$2:$D$88,TRUE())>0,"TRUE","FALSE")) -> TRUE | E16: =IF(COUNTIFS('Threat Scenarios'!$C$2:$C$88,$A16,'Threat Scenarios'!$E$2:$E$88,E$15)=0,"n/a",IF(COUNTIFS('Threat Scenarios'!$C$2:$C$88,$A16,'Threat Scenarios'!$E$2:$E$88,E$15,'Threat Scenarios'!$D$2:$D$88,TRUE())>0,"TRUE","FALSE")) -> TRUE | F16: =IF(COUNTIFS('Threat Scenarios'!$C$2:$C$88,$A16,'Threat Scenarios'!$E$2:$E$88,F$15)=0,"n/a",IF(COUNTIFS('Threat Scenarios'!$C$2:$C$88,$A16,'Threat Scenarios'!$E$2:$E$88,F$15,'Threat Scenarios'!$D$2:$D$88,TRUE())>0,"TRUE","FALSE")) -> TRUE | G16: =IF(COUNTIFS('Threat Scenarios'!$C$2:$C$88,$A16,'Threat Scenarios'!$E$2:$E$88,G$15)=0,"n/a",IF(COUNTIFS('Threat Scenarios'!$C$2:$C$88,$A16,'Threat Scenarios'!$E$2:$E$88,G$15,'Threat Scenarios'!$D$2:$D$88,TRUE())>0,"TRUE","FALSE")) -> TRUE | H16: =COUNTIFS('Threat Scenarios'!$C$2:$C$88,$A16,'Threat Scenarios'!$D$2:$D$88,TRUE()) -> 6
A17: Perception Module | B17: =IF(COUNTIFS('Threat Scenarios'!$C$2:$C$88,$A17,'Threat Scenarios'!$E$2:$E$88,B$15)=0,"n/a",IF(COUNTIFS('Threat Scenarios'!$C$2:$C$88,$A17,'Threat Scenarios'!$E$2:$E$88,B$15,'Threat Scenarios'!$D$2:$D$88,TRUE())>0,"TRUE","FALSE")) -> TRUE | C17: =IF(COUNTIFS('Threat Scenarios'!$C$2:$C$88,$A17,'Threat Scenarios'!$E$2:$E$88,C$15)=0,"n/a",IF(COUNTIFS('Threat Scenarios'!$C$2:$C$88,$A17,'Threat Scenarios'!$E$2:$E$88,C$15,'Threat Scenarios'!$D$2:$D$88,TRUE())>0,"TRUE","FALSE")) -> TRUE | D17: =IF(COUNTIFS('Threat Scenarios'!$C$2:$C$88,$A17,'Threat Scenarios'!$E$2:$E$88,D$15)=0,"n/a",IF(COUNTIFS('Threat Scenarios'!$C$2:$C$88,$A17,'Threat Scenarios'!$E$2:$E$88,D$15,'Threat Scenarios'!$D$2:$D$88,TRUE())>0,"TRUE","FALSE")) -> FALSE | E17: =IF(COUNTIFS('Threat Scenarios'!$C$2:$C$88,$A17,'Threat Scenarios'!$E$2:$E$88,E$15)=0,"n/a",IF(COUNTIFS('Threat Scenarios'!$C$2:$C$88,$A17,'Threat Scenarios'!$E$2:$E$88,E$15,'Threat Scenarios'!$D$2:$D$88,TRUE())>0,"TRUE","FALSE")) -> TRUE | F17: =IF(COUNTIFS('Threat Scenarios'!$C$2:$C$88,$A17,'Threat Scenarios'!$E$2:$E$88,F$15)=0,"n/a",IF(COUNTIFS('Threat Scenarios'!$C$2:$C$88,$A17,'Threat Scenarios'!$E$2:$E$88,F$15,'Threat Scenarios'!$D$2:$D$88,TRUE())>0,"TRUE","FALSE")) -> TRUE | G17: =IF(COUNTIFS('Threat Scenarios'!$C$2:$C$88,$A17,'Threat Scenarios'!$E$2:$E$88,G$15)=0,"n/a",IF(COUNTIFS('Threat Scenarios'!$C$2:$C$88,$A17,'Threat Scenarios'!$E$2:$E$88,G$15,'Threat Scenarios'!$D$2:$D$88,TRUE())>0,"TRUE","FALSE")) -> TRUE | H17: =COUNTIFS('Threat Scenarios'!$C$2:$C$88,$A17,'Threat Scenarios'!$D$2:$D$88,TRUE()) -> 5
A18: Actuation Module | B18: =IF(COUNTIFS('Threat Scenarios'!$C$2:$C$88,$A18,'Threat Scenarios'!$E$2:$E$88,B$15)=0,"n/a",IF(COUNTIFS('Threat Scenarios'!$C$2:$C$88,$A18,'Threat Scenarios'!$E$2:$E$88,B$15,'Threat Scenarios'!$D$2:$D$88,TRUE())>0,"TRUE","FALSE")) -> TRUE | C18: =IF(COUNTIFS('Threat Scenarios'!$C$2:$C$88,$A18,'Threat Scenarios'!$E$2:$E$88,C$15)=0,"n/a",IF(COUNTIFS('Threat Scenarios'!$C$2:$C$88,$A18,'Threat Scenarios'!$E$2:$E$88,C$15,'Threat Scenarios'!$D$2:$D$88,TRUE())>0,"TRUE","FALSE")) -> TRUE | D18: =IF(COUNTIFS('Threat Scenarios'!$C$2:$C$88,$A18,'Threat Scenarios'!$E$2:$E$88,D$15)=0,"n/a",IF(COUNTIFS('Threat Scenarios'!$C$2:$C$88,$A18,'Threat Scenarios'!$E$2:$E$88,D$15,'Threat Scenarios'!$D$2:$D$88,TRUE())>0,"TRUE","FALSE")) -> FALSE | E18: =IF(COUNTIFS('Threat Scenarios'!$C$2:$C$88,$A18,'Threat Scenarios'!$E$2:$E$88,E$15)=0,"n/a",IF(COUNTIFS('Threat Scenarios'!$C$2:$C$88,$A18,'Threat Scenarios'!$E$2:$E$88,E$15,'Threat Scenarios'!$D$2:$D$88,TRUE())>0,"TRUE","FALSE")) -> FALSE | F18: =IF(COUNTIFS('Threat Scenarios'!$C$2:$C$88,$A18,'Threat Scenarios'!$E$2:$E$88,F$15)=0,"n/a",IF(COUNTIFS('Threat Scenarios'!$C$2:$C$88,$A18,'Threat Scenarios'!$E$2:$E$88,F$15,'Threat Scenarios'!$D$2:$D$88,TRUE())>0,"TRUE","FALSE")) -> TRUE | G18: =IF(COUNTIFS('Threat Scenarios'!$C$2:$C$88,$A18,'Threat Scenarios'!$E$2:$E$88,G$15)=0,"n/a",IF(COUNTIFS('Threat Scenarios'!$C$2:$C$88,$A18,'Threat Scenarios'!$E$2:$E$88,G$15,'Threat Scenarios'!$D$2:$D$88,TRUE())>0,"TRUE","FALSE")) -> TRUE | H18: =COUNTIFS('Threat Scenarios'!$C$2:$C$88,$A18,'Threat Scenarios'!$D$2:$D$88,TRUE()) -> 4
A19: Camera | B19: =IF(COUNTIFS('Threat Scenarios'!$C$2:$C$88,$A19,'Threat Scenarios'!$E$2:$E$88,B$15)=0,"n/a",IF(COUNTIFS('Threat Scenarios'!$C$2:$C$88,$A19,'Threat Scenarios'!$E$2:$E$88,B$15,'Threat Scenarios'!$D$2:$D$88,TRUE())>0,"TRUE","FALSE")) -> TRUE | C19: =IF(COUNTIFS('Threat Scenarios'!$C$2:$C$88,$A19,'Threat Scenarios'!$E$2:$E$88,C$15)=0,"n/a",IF(COUNTIFS('Threat Scenarios'!$C$2:$C$88,$A19,'Threat Scenarios'!$E$2:$E$88,C$15,'Threat Scenarios'!$D$2:$D$88,TRUE())>0,"TRUE","FALSE")) -> TRUE | D19: =IF(COUNTIFS('Threat Scenarios'!$C$2:$C$88,$A19,'Threat Scenarios'!$E$2:$E$88,D$15)=0,"n/a",IF(COUNTIFS('Threat Scenarios'!$C$2:$C$88,$A19,'Threat Scenarios'!$E$2:$E$88,D$15,'Threat Scenarios'!$D$2:$D$88,TRUE())>0,"TRUE","FALSE")) -> FALSE | E19: =IF(COUNTIFS('Threat Scenarios'!$C$2:$C$88,$A19,'Threat Scenarios'!$E$2:$E$88,E$15)=0,"n/a",IF(COUNTIFS('Threat Scenarios'!$C$2:$C$88,$A19,'Threat Scenarios'!$E$2:$E$88,E$15,'Threat Scenarios'!$D$2:$D$88,TRUE())>0,"TRUE","FALSE")) -> FALSE | F19: =IF(COUNTIFS('Threat Scenarios'!$C$2:$C$88,$A19,'Threat Scenarios'!$E$2:$E$88,F$15)=0,"n/a",IF(COUNTIFS('Threat Scenarios'!$C$2:$C$88,$A19,'Threat Scenarios'!$E$2:$E$88,F$15,'Threat Scenarios'!$D$2:$D$88,TRUE())>0,"TRUE","FALSE")) -> TRUE | G19: =IF(COUNTIFS('Threat Scenarios'!$C$2:$C$88,$A19,'Threat Scenarios'!$E$2:$E$88,G$15)=0,"n/a",IF(COUNTIFS('Threat Scenarios'!$C$2:$C$88,$A19,'Threat Scenarios'!$E$2:$E$88,G$15,'Threat Scenarios'!$D$2:$D$88,TRUE())>0,"TRUE","FALSE")) -> FALSE | H19: =COUNTIFS('Threat Scenarios'!$C$2:$C$88,$A19,'Threat Scenarios'!$D$2:$D$88,TRUE()) -> 3
A20: Radar | B20: =IF(COUNTIFS('Threat Scenarios'!$C$2:$C$88,$A20,'Threat Scenarios'!$E$2:$E$88,B$15)=0,"n/a",IF(COUNTIFS('Threat Scenarios'!$C$2:$C$88,$A20,'Threat Scenarios'!$E$2:$E$88,B$15,'Threat Scenarios'!$D$2:$D$88,TRUE())>0,"TRUE","FALSE")) -> TRUE | C20: =IF(COUNTIFS('Threat Scenarios'!$C$2:$C$88,$A20,'Threat Scenarios'!$E$2:$E$88,C$15)=0,"n/a",IF(COUNTIFS('Threat Scenarios'!$C$2:$C$88,$A20,'Threat Scenarios'!$E$2:$E$88,C$15,'Threat Scenarios'!$D$2:$D$88,TRUE())>0,"TRUE","FALSE")) -> TRUE | D20: =IF(COUNTIFS('Threat Scenarios'!$C$2:$C$88,$A20,'Threat Scenarios'!$E$2:$E$88,D$15)=0,"n/a",IF(COUNTIFS('Threat Scenarios'!$C$2:$C$88,$A20,'Threat Scenarios'!$E$2:$E$88,D$15,'Threat Scenarios'!$D$2:$D$88,TRUE())>0,"TRUE","FALSE")) -> FALSE | E20: =IF(COUNTIFS('Threat Scenarios'!$C$2:$C$88,$A20,'Threat Scenarios'!$E$2:$E$88,E$15)=0,"n/a",IF(COUNTIFS('Threat Scenarios'!$C$2:$C$88,$A20,'Threat Scenarios'!$E$2:$E$88,E$15,'Threat Scenarios'!$D$2:$D$88,TRUE())>0,"TRUE","FALSE")) -> FALSE | F20: =IF(COUNTIFS('Threat Scenarios'!$C$2:$C$88,$A20,'Threat Scenarios'!$E$2:$E$88,F$15)=0,"n/a",IF(COUNTIFS('Threat Scenarios'!$C$2:$C$88,$A20,'Threat Scenarios'!$E$2:$E$88,F$15,'Threat Scenarios'!$D$2:$D$88,TRUE())>0,"TRUE","FALSE")) -> TRUE | G20: =IF(COUNTIFS('Threat Scenarios'!$C$2:$C$88,$A20,'Threat Scenarios'!$E$2:$E$88,G$15)=0,"n/a",IF(COUNTIFS('Threat Scenarios'!$C$2:$C$88,$A20,'Threat Scenarios'!$E$2:$E$88,G$15,'Threat Scenarios'!$D$2:$D$88,TRUE())>0,"TRUE","FALSE")) -> FALSE | H20: =COUNTIFS('Threat Scenarios'!$C$2:$C$88,$A20,'Threat Scenarios'!$D$2:$D$88,TRUE()) -> 3
A21: LIDAR | B21: =IF(COUNTIFS('Threat Scenarios'!$C$2:$C$88,$A21,'Threat Scenarios'!$E$2:$E$88,B$15)=0,"n/a",IF(COUNTIFS('Threat Scenarios'!$C$2:$C$88,$A21,'Threat Scenarios'!$E$2:$E$88,B$15,'Threat Scenarios'!$D$2:$D$88,TRUE())>0,"TRUE","FALSE")) -> TRUE | C21: =IF(COUNTIFS('Threat Scenarios'!$C$2:$C$88,$A21,'Threat Scenarios'!$E$2:$E$88,C$15)=0,"n/a",IF(COUNTIFS('Threat Scenarios'!$C$2:$C$88,$A21,'Threat Scenarios'!$E$2:$E$88,C$15,'Threat Scenarios'!$D$2:$D$88,TRUE())>0,"TRUE","FALSE")) -> TRUE | D21: =IF(COUNTIFS('Threat Scenarios'!$C$2:$C$88,$A21,'Threat Scenarios'!$E$2:$E$88,D$15)=0,"n/a",IF(COUNTIFS('Threat Scenarios'!$C$2:$C$88,$A21,'Threat Scenarios'!$E$2:$E$88,D$15,'Threat Scenarios'!$D$2:$D$88,TRUE())>0,"TRUE","FALSE")) -> FALSE | E21: =IF(COUNTIFS('Threat Scenarios'!$C$2:$C$88,$A21,'Threat Scenarios'!$E$2:$E$88,E$15)=0,"n/a",IF(COUNTIFS('Threat Scenarios'!$C$2:$C$88,$A21,'Threat Scenarios'!$E$2:$E$88,E$15,'Threat Scenarios'!$D$2:$D$88,TRUE())>0,"TRUE","FALSE")) -> FALSE | F21: =IF(COUNTIFS('Threat Scenarios'!$C$2:$C$88,$A21,'Threat Scenarios'!$E$2:$E$88,F$15)=0,"n/a",IF(COUNTIFS('Threat Scenarios'!$C$2:$C$88,$A21,'Threat Scenarios'!$E$2:$E$88,F$15,'Threat Scenarios'!$D$2:$D$88,TRUE())>0,"TRUE","FALSE")) -> TRUE | G21: =IF(COUNTIFS('Threat Scenarios'!$C$2:$C$88,$A21,'Threat Scenarios'!$E$2:$E$88,G$15)=0,"n/a",IF(COUNTIFS('Threat Scenarios'!$C$2:$C$88,$A21,'Threat Scenarios'!$E$2:$E$88,G$15,'Threat Scenarios'!$D$2:$D$88,TRUE())>0,"TRUE","FALSE")) -> FALSE | H21: =COUNTIFS('Threat Scenarios'!$C$2:$C$88,$A21,'Threat Scenarios'!$D$2:$D$88,TRUE()) -> 3
A22: OBU | B22: =IF(COUNTIFS('Threat Scenarios'!$C$2:$C$88,$A22,'Threat Scenarios'!$E$2:$E$88,B$15)=0,"n/a",IF(COUNTIFS('Threat Scenarios'!$C$2:$C$88,$A22,'Threat Scenarios'!$E$2:$E$88,B$15,'Threat Scenarios'!$D$2:$D$88,TRUE())>0,"TRUE","FALSE")) -> TRUE | C22: =IF(COUNTIFS('Threat Scenarios'!$C$2:$C$88,$A22,'Threat Scenarios'!$E$2:$E$88,C$15)=0,"n/a",IF(COUNTIFS('Threat Scenarios'!$C$2:$C$88,$A22,'Threat Scenarios'!$E$2:$E$88,C$15,'Threat Scenarios'!$D$2:$D$88,TRUE())>0,"TRUE","FALSE")) -> TRUE | D22: =IF(COUNTIFS('Threat Scenarios'!$C$2:$C$88,$A22,'Threat Scenarios'!$E$2:$E$88,D$15)=0,"n/a",IF(COUNTIFS('Threat Scenarios'!$C$2:$C$88,$A22,'Threat Scenarios'!$E$2:$E$88,D$15,'Threat Scenarios'!$D$2:$D$88,TRUE())>0,"TRUE","FALSE")) -> TRUE | E22: =IF(COUNTIFS('Threat Scenarios'!$C$2:$C$88,$A22,'Threat Scenarios'!$E$2:$E$88,E$15)=0,"n/a",IF(COUNTIFS('Threat Scenarios'!$C$2:$C$88,$A22,'Threat Scenarios'!$E$2:$E$88,E$15,'Threat Scenarios'!$D$2:$D$88,TRUE())>0,"TRUE","FALSE")) -> TRUE | F22: =IF(COUNTIFS('Threat Scenarios'!$C$2:$C$88,$A22,'Threat Scenarios'!$E$2:$E$88,F$15)=0,"n/a",IF(COUNTIFS('Threat Scenarios'!$C$2:$C$88,$A22,'Threat Scenarios'!$E$2:$E$88,F$15,'Threat Scenarios'!$D$2:$D$88,TRUE())>0,"TRUE","FALSE")) -> TRUE | G22: =IF(COUNTIFS('Threat Scenarios'!$C$2:$C$88,$A22,'Threat Scenarios'!$E$2:$E$88,G$15)=0,"n/a",IF(COUNTIFS('Threat Scenarios'!$C$2:$C$88,$A22,'Threat Scenarios'!$E$2:$E$88,G$15,'Threat Scenarios'!$D$2:$D$88,TRUE())>0,"TRUE","FALSE")) -> TRUE | H22: =COUNTIFS('Threat Scenarios'!$C$2:$C$88,$A22,'Threat Scenarios'!$D$2:$D$88,TRUE()) -> 6
A23: Brake | B23: =IF(COUNTIFS('Threat Scenarios'!$C$2:$C$88,$A23,'Threat Scenarios'!$E$2:$E$88,B$15)=0,"n/a",IF(COUNTIFS('Threat Scenarios'!$C$2:$C$88,$A23,'Threat Scenarios'!$E$2:$E$88,B$15,'Threat Scenarios'!$D$2:$D$88,TRUE())>0,"TRUE","FALSE")) -> FALSE | C23: =IF(COUNTIFS('Threat Scenarios'!$C$2:$C$88,$A23,'Threat Scenarios'!$E$2:$E$88,C$15)=0,"n/a",IF(COUNTIFS('Threat Scenarios'!$C$2:$C$88,$A23,'Threat Scenarios'!$E$2:$E$88,C$15,'Threat Scenarios'!$D$2:$D$88,TRUE())>0,"TRUE","FALSE")) -> TRUE | D23: =IF(COUNTIFS('Threat Scenarios'!$C$2:$C$88,$A23,'Threat Scenarios'!$E$2:$E$88,D$15)=0,"n/a",IF(COUNTIFS('Threat Scenarios'!$C$2:$C$88,$A23,'Threat Scenarios'!$E$2:$E$88,D$15,'Threat Scenarios'!$D$2:$D$88,TRUE())>0,"TRUE","FALSE")) -> FALSE | E23: =IF(COUNTIFS('Threat Scenarios'!$C$2:$C$88,$A23,'Threat Scenarios'!$E$2:$E$88,E$15)=0,"n/a",IF(COUNTIFS('Threat Scenarios'!$C$2:$C$88,$A23,'Threat Scenarios'!$E$2:$E$88,E$15,'Threat Scenarios'!$D$2:$D$88,TRUE())>0,"TRUE","FALSE")) -> FALSE | F23: =IF(COUNTIFS('Threat Scenarios'!$C$2:$C$88,$A23,'Threat Scenarios'!$E$2:$E$88,F$15)=0,"n/a",IF(COUNTIFS('Threat Scenarios'!$C$2:$C$88,$A23,'Threat Scenarios'!$E$2:$E$88,F$15,'Threat Scenarios'!$D$2:$D$88,TRUE())>0,"TRUE","FALSE")) -> TRUE | G23: =IF(COUNTIFS('Threat Scenarios'!$C$2:$C$88,$A23,'Threat Scenarios'!$E$2:$E$88,G$15)=0,"n/a",IF(COUNTIFS('Threat Scenarios'!$C$2:$C$88,$A23,'Threat Scenarios'!$E$2:$E$88,G$15,'Threat Scenarios'!$D$2:$D$88,TRUE())>0,"TRUE","FALSE")) -> FALSE | H23: =COUNTIFS('Threat Scenarios'!$C$2:$C$88,$A23,'Threat Scenarios'!$D$2:$D$88,TRUE()) -> 2
A24: Throttle | B24: =IF(COUNTIFS('Threat Scenarios'!$C$2:$C$88,$A24,'Threat Scenarios'!$E$2:$E$88,B$15)=0,"n/a",IF(COUNTIFS('Threat Scenarios'!$C$2:$C$88,$A24,'Threat Scenarios'!$E$2:$E$88,B$15,'Threat Scenarios'!$D$2:$D$88,TRUE())>0,"TRUE","FALSE")) -> FALSE | C24: =IF(COUNTIFS('Threat Scenarios'!$C$2:$C$88,$A24,'Threat Scenarios'!$E$2:$E$88,C$15)=0,"n/a",IF(COUNTIFS('Threat Scenarios'!$C$2:$C$88,$A24,'Threat Scenarios'!$E$2:$E$88,C$15,'Threat Scenarios'!$D$2:$D$88,TRUE())>0,"TRUE","FALSE")) -> TRUE | D24: =IF(COUNTIFS('Threat Scenarios'!$C$2:$C$88,$A24,'Threat Scenarios'!$E$2:$E$88,D$15)=0,"n/a",IF(COUNTIFS('Threat Scenarios'!$C$2:$C$88,$A24,'Threat Scenarios'!$E$2:$E$88,D$15,'Threat Scenarios'!$D$2:$D$88,TRUE())>0,"TRUE","FALSE")) -> FALSE | E24: =IF(COUNTIFS('Threat Scenarios'!$C$2:$C$88,$A24,'Threat Scenarios'!$E$2:$E$88,E$15)=0,"n/a",IF(COUNTIFS('Threat Scenarios'!$C$2:$C$88,$A24,'Threat Scenarios'!$E$2:$E$88,E$15,'Threat Scenarios'!$D$2:$D$88,TRUE())>0,"TRUE","FALSE")) -> FALSE | F24: =IF(COUNTIFS('Threat Scenarios'!$C$2:$C$88,$A24,'Threat Scenarios'!$E$2:$E$88,F$15)=0,"n/a",IF(COUNTIFS('Threat Scenarios'!$C$2:$C$88,$A24,'Threat Scenarios'!$E$2:$E$88,F$15,'Threat Scenarios'!$D$2:$D$88,TRUE())>0,"TRUE","FALSE")) -> TRUE | G24: =IF(COUNTIFS('Threat Scenarios'!$C$2:$C$88,$A24,'Threat Scenarios'!$E$2:$E$88,G$15)=0,"n/a",IF(COUNTIFS('Threat Scenarios'!$C$2:$C$88,$A24,'Threat Scenarios'!$E$2:$E$88,G$15,'Threat Scenarios'!$D$2:$D$88,TRUE())>0,"TRUE","FALSE")) -> FALSE | H24: =COUNTIFS('Threat Scenarios'!$C$2:$C$88,$A24,'Threat Scenarios'!$D$2:$D$88,TRUE()) -> 2
A25: AEB | B25: =IF(COUNTIFS('Threat Scenarios'!$C$2:$C$88,$A25,'Threat Scenarios'!$E$2:$E$88,B$15)=0,"n/a",IF(COUNTIFS('Threat Scenarios'!$C$2:$C$88,$A25,'Threat Scenarios'!$E$2:$E$88,B$15,'Threat Scenarios'!$D$2:$D$88,TRUE())>0,"TRUE","FALSE")) -> FALSE | C25: =IF(COUNTIFS('Threat Scenarios'!$C$2:$C$88,$A25,'Threat Scenarios'!$E$2:$E$88,C$15)=0,"n/a",IF(COUNTIFS('Threat Scenarios'!$C$2:$C$88,$A25,'Threat Scenarios'!$E$2:$E$88,C$15,'Threat Scenarios'!$D$2:$D$88,TRUE())>0,"TRUE","FALSE")) -> TRUE | D25: =IF(COUNTIFS('Threat Scenarios'!$C$2:$C$88,$A25,'Threat Scenarios'!$E$2:$E$88,D$15)=0,"n/a",IF(COUNTIFS('Threat Scenarios'!$C$2:$C$88,$A25,'Threat Scenarios'!$E$2:$E$88,D$15,'Threat Scenarios'!$D$2:$D$88,TRUE())>0,"TRUE","FALSE")) -> FALSE | E25: =IF(COUNTIFS('Threat Scenarios'!$C$2:$C$88,$A25,'Threat Scenarios'!$E$2:$E$88,E$15)=0,"n/a",IF(COUNTIFS('Threat Scenarios'!$C$2:$C$88,$A25,'Threat Scenarios'!$E$2:$E$88,E$15,'Threat Scenarios'!$D$2:$D$88,TRUE())>0,"TRUE","FALSE")) -> FALSE | F25: =IF(COUNTIFS('Threat Scenarios'!$C$2:$C$88,$A25,'Threat Scenarios'!$E$2:$E$88,F$15)=0,"n/a",IF(COUNTIFS('Threat Scenarios'!$C$2:$C$88,$A25,'Threat Scenarios'!$E$2:$E$88,F$15,'Threat Scenarios'!$D$2:$D$88,TRUE())>0,"TRUE","FALSE")) -> TRUE | G25: =IF(COUNTIFS('Threat Scenarios'!$C$2:$C$88,$A25,'Threat Scenarios'!$E$2:$E$88,G$15)=0,"n/a",IF(COUNTIFS('Threat Scenarios'!$C$2:$C$88,$A25,'Threat Scenarios'!$E$2:$E$88,G$15,'Threat Scenarios'!$D$2:$D$88,TRUE())>0,"TRUE","FALSE")) -> FALSE | H25: =COUNTIFS('Threat Scenarios'!$C$2:$C$88,$A25,'Threat Scenarios'!$D$2:$D$88,TRUE()) -> 2
A26: C Out → PM In (Camera data) | B26: =IF(COUNTIFS('Threat Scenarios'!$C$2:$C$88,$A26,'Threat Scenarios'!$E$2:$E$88,B$15)=0,"n/a",IF(COUNTIFS('Threat Scenarios'!$C$2:$C$88,$A26,'Threat Scenarios'!$E$2:$E$88,B$15,'Threat Scenarios'!$D$2:$D$88,TRUE())>0,"TRUE","FALSE")) -> n/a | C26: =IF(COUNTIFS('Threat Scenarios'!$C$2:$C$88,$A26,'Threat Scenarios'!$E$2:$E$88,C$15)=0,"n/a",IF(COUNTIFS('Threat Scenarios'!$C$2:$C$88,$A26,'Threat Scenarios'!$E$2:$E$88,C$15,'Threat Scenarios'!$D$2:$D$88,TRUE())>0,"TRUE","FALSE")) -> TRUE | D26: =IF(COUNTIFS('Threat Scenarios'!$C$2:$C$88,$A26,'Threat Scenarios'!$E$2:$E$88,D$15)=0,"n/a",IF(COUNTIFS('Threat Scenarios'!$C$2:$C$88,$A26,'Threat Scenarios'!$E$2:$E$88,D$15,'Threat Scenarios'!$D$2:$D$88,TRUE())>0,"TRUE","FALSE")) -> n/a | E26: =IF(COUNTIFS('Threat Scenarios'!$C$2:$C$88,$A26,'Threat Scenarios'!$E$2:$E$88,E$15)=0,"n/a",IF(COUNTIFS('Threat Scenarios'!$C$2:$C$88,$A26,'Threat Scenarios'!$E$2:$E$88,E$15,'Threat Scenarios'!$D$2:$D$88,TRUE())>0,"TRUE","FALSE")) -> TRUE | F26: =IF(COUNTIFS('Threat Scenarios'!$C$2:$C$88,$A26,'Threat Scenarios'!$E$2:$E$88,F$15)=0,"n/a",IF(COUNTIFS('Threat Scenarios'!$C$2:$C$88,$A26,'Threat Scenarios'!$E$2:$E$88,F$15,'Threat Scenarios'!$D$2:$D$88,TRUE())>0,"TRUE","FALSE")) -> TRUE | G26: =IF(COUNTIFS('Threat Scenarios'!$C$2:$C$88,$A26,'Threat Scenarios'!$E$2:$E$88,G$15)=0,"n/a",IF(COUNTIFS('Threat Scenarios'!$C$2:$C$88,$A26,'Threat Scenarios'!$E$2:$E$88,G$15,'Threat Scenarios'!$D$2:$D$88,TRUE())>0,"TRUE","FALSE")) -> n/a | H26: =COUNTIFS('Threat Scenarios'!$C$2:$C$88,$A26,'Threat Scenarios'!$D$2:$D$88,TRUE()) -> 3
A27: R Out → PM In (Radar data) | B27: =IF(COUNTIFS('Threat Scenarios'!$C$2:$C$88,$A27,'Threat Scenarios'!$E$2:$E$88,B$15)=0,"n/a",IF(COUNTIFS('Threat Scenarios'!$C$2:$C$88,$A27,'Threat Scenarios'!$E$2:$E$88,B$15,'Threat Scenarios'!$D$2:$D$88,TRUE())>0,"TRUE","FALSE")) -> n/a | C27: =IF(COUNTIFS('Threat Scenarios'!$C$2:$C$88,$A27,'Threat Scenarios'!$E$2:$E$88,C$15)=0,"n/a",IF(COUNTIFS('Threat Scenarios'!$C$2:$C$88,$A27,'Threat Scenarios'!$E$2:$E$88,C$15,'Threat Scenarios'!$D$2:$D$88,TRUE())>0,"TRUE","FALSE")) -> TRUE | D27: =IF(COUNTIFS('Threat Scenarios'!$C$2:$C$88,$A27,'Threat Scenarios'!$E$2:$E$88,D$15)=0,"n/a",IF(COUNTIFS('Threat Scenarios'!$C$2:$C$88,$A27,'Threat Scenarios'!$E$2:$E$88,D$15,'Threat Scenarios'!$D$2:$D$88,TRUE())>0,"TRUE","FALSE")) -> n/a | E27: =IF(COUNTIFS('Threat Scenarios'!$C$2:$C$88,$A27,'Threat Scenarios'!$E$2:$E$88,E$15)=0,"n/a",IF(COUNTIFS('Threat Scenarios'!$C$2:$C$88,$A27,'Threat Scenarios'!$E$2:$E$88,E$15,'Threat Scenarios'!$D$2:$D$88,TRUE())>0,"TRUE","FALSE")) -> FALSE | F27: =IF(COUNTIFS('Threat Scenarios'!$C$2:$C$88,$A27,'Threat Scenarios'!$E$2:$E$88,F$15)=0,"n/a",IF(COUNTIFS('Threat Scenarios'!$C$2:$C$88,$A27,'Threat Scenarios'!$E$2:$E$88,F$15,'Threat Scenarios'!$D$2:$D$88,TRUE())>0,"TRUE","FALSE")) -> TRUE | G27: =IF(COUNTIFS('Threat Scenarios'!$C$2:$C$88,$A27,'Threat Scenarios'!$E$2:$E$88,G$15)=0,"n/a",IF(COUNTIFS('Threat Scenarios'!$C$2:$C$88,$A27,'Threat Scenarios'!$E$2:$E$88,G$15,'Threat Scenarios'!$D$2:$D$88,TRUE())>0,"TRUE","FALSE")) -> n/a | H27: =COUNTIFS('Threat Scenarios'!$C$2:$C$88,$A27,'Threat Scenarios'!$D$2:$D$88,TRUE()) -> 2
... A34: AM Out → AEB In (AEB command) | B34: =IF(COUNTIFS('Threat Scenarios'!$C$2:$C$88,$A34,'Threat Scenarios'!$E$2:$E$88,B$15)=0,"n/a",IF(COUNTIFS('Threat Scenarios'!$C$2:$C$88,$A34,'Threat Scenarios'!$E$2:$E$88,B$15,'Threat Scenarios'!$D$2:$D$88,TRUE())>0,"TRUE","FALSE")) -> n/a | C34: =IF(COUNTIFS('Threat Scenarios'!$C$2:$C$88,$A34,'Threat Scenarios'!$E$2:$E$88,C$15)=0,"n/a",IF(COUNTIFS('Threat Scenarios'!$C$2:$C$88,$A34,'Threat Scenarios'!$E$2:$E$88,C$15,'Threat Scenarios'!$D$2:$D$88,TRUE())>0,"TRUE","FALSE")) -> TRUE | D34: =IF(COUNTIFS('Threat Scenarios'!$C$2:$C$88,$A34,'Threat Scenarios'!$E$2:$E$88,D$15)=0,"n/a",IF(COUNTIFS('Threat Scenarios'!$C$2:$C$88,$A34,'Threat Scenarios'!$E$2:$E$88,D$15,'Threat Scenarios'!$D$2:$D$88,TRUE())>0,"TRUE","FALSE")) -> n/a | E34: =IF(COUNTIFS('Threat Scenarios'!$C$2:$C$88,$A34,'Threat Scenarios'!$E$2:$E$88,E$15)=0,"n/a",IF(COUNTIFS('Threat Scenarios'!$C$2:$C$88,$A34,'Threat Scenarios'!$E$2:$E$88,E$15,'Threat Scenarios'!$D$2:$D$88,TRUE())>0,"TRUE","FALSE")) -> FALSE | F34: =IF(COUNTIFS('Threat Scenarios'!$C$2:$C$88,$A34,'Threat Scenarios'!$E$2:$E$88,F$15)=0,"n/a",IF(COUNTIFS('Threat Scenarios'!$C$2:$C$88,$A34,'Threat Scenarios'!$E$2:$E$88,F$15,'Threat Scenarios'!$D$2:$D$88,TRUE())>0,"TRUE","FALSE")) -> TRUE | G34: =IF(COUNTIFS('Threat Scenarios'!$C$2:$C$88,$A34,'Threat Scenarios'!$E$2:$E$88,G$15)=0,"n/a",IF(COUNTIFS('Threat Scenarios'!$C$2:$C$88,$A34,'Threat Scenarios'!$E$2:$E$88,G$15,'Threat Scenarios'!$D$2:$D$88,TRUE())>0,"TRUE","FALSE")) -> n/a | H34: =COUNTIFS('Threat Scenarios'!$C$2:$C$88,$A34,'Threat Scenarios'!$D$2:$D$88,TRUE()) -> 2

Sheet Notes
A1: TARA of AI-based ACC - AI engine output: scope, method and assessment criteria
A3: 1. Scope
A4: Assets are taken from the medini analyze architecture model so that both TARAs start from the same item definition.
A5: Elements (10): AI Controller Module (upper level), Perception Module with Camera, Radar, LIDAR and OBU, Actuation Module with Brake, Throttle and AEB.
A6: Connections (9): the port-to-port links shown in the medini model (C Out, R Out, L Out, OBU Out → PM In; PM Out → AI In; AI Out → AM In; AM Out → B In, T In, AEB In).
A7: Not included: the direct Perception → Actuation link and the Continuous Vehicle Dynamics Monitoring Module shown in the general architecture, because they are not part of the medini model.
A9: 2. Method
A10: STRIDE: Spoofing (authenticity), Tampering (integrity), Repudiation (non-repudiation), Information Disclosure (confidentiality), Denial of Service (availability), Elevation of Privilege (authorization).
A11: Architecture elements: all six STRIDE categories are applied to every element, one threat scenario per element and category.
A12: Connections: Tampering, Information Disclosure and Denial of Service only (STRIDE-per-element rule for data flows). Spoofing of a flow's source is covered by the Spoofing scenario of the sending element.
A13: IDs run element by element in the order of the medini model, then connection by connection.
A15: 3. To Be Assessed criteria
... A25: Adversarial inputs and physical adversarial patches (Spoofing of Camera, Radar, LIDAR); model poisoning and backdoors (Tampering with AI Controller Module); model extraction (Information Disclosure of AI Controller Module); sponge examples / inference latency attacks (Denial of Service on AI Controller Module).
