Workbook

Sheet TARA
A1: ID | B1: Name | C1: Assets | D1: To Be Assessed | E1: Category
A2: TS-001 | B2: Spoofing of AI Controller Module | C2: AI Controller Module | D2: =TRUE() -> TRUE | E2: Spoofing
A3: TS-002 | B3: Tampering with AI Controller Module | C3: AI Controller Module | D3: =TRUE() -> TRUE | E3: Tampering
A4: TS-003 | B4: Repudiation of AI Controller Module actions | C4: AI Controller Module | D4: =TRUE() -> TRUE | E4: Repudiation
A5: TS-004 | B5: Information disclosure from AI Controller Module | C5: AI Controller Module | D5: =TRUE() -> TRUE | E5: Information Disclosure
A6: TS-005 | B6: Denial of service of AI Controller Module | C6: AI Controller Module | D6: =TRUE() -> TRUE | E6: Denial of Service
A7: TS-006 | B7: Elevation of privilege on AI Controller Module | C7: AI Controller Module | D7: =TRUE() -> TRUE | E7: Elevation of Privilege
A8: TS-007 | B8: Spoofing of Perception Module | C8: Perception Module | D8: =TRUE() -> TRUE | E8: Spoofing
A9: TS-008 | B9: Tampering with Perception Module | C9: Perception Module | D9: =TRUE() -> TRUE | E9: Tampering
A10: TS-009 | B10: Repudiation of Perception Module actions | C10: Perception Module | D10: =FALSE() -> FALSE | E10: Repudiation
A11: TS-010 | B11: Information disclosure from Perception Module | C11: Perception Module | D11: =TRUE() -> TRUE | E11: Information Disclosure
A12: TS-011 | B12: Denial of service of Perception Module | C12: Perception Module | D12: =TRUE() -> TRUE | E12: Denial of Service
A13: TS-012 | B13: Elevation of privilege on Perception Module | C13: Perception Module | D13: =TRUE() -> TRUE | E13: Elevation of Privilege
A14: TS-013 | B14: Spoofing of Camera | C14: Camera | D14: =TRUE() -> TRUE | E14: Spoofing
A15: TS-014 | B15: Tampering with Camera | C15: Camera | D15: =TRUE() -> TRUE | E15: Tampering
A16: TS-015 | B16: Repudiation of Camera actions | C16: Camera | D16: =FALSE() -> FALSE | E16: Repudiation
A17: TS-016 | B17: Information disclosure from Camera | C17: Camera | D17: =FALSE() -> FALSE | E17: Information Disclosure
A18: TS-017 | B18: Denial of service of Camera | C18: Camera | D18: =TRUE() -> TRUE | E18: Denial of Service
A19: TS-018 | B19: Elevation of privilege on Camera | C19: Camera | D19: =FALSE() -> FALSE | E19: Elevation of Privilege
A20: TS-019 | B20: Spoofing of Radar | C20: Radar | D20: =TRUE() -> TRUE | E20: Spoofing
A21: TS-020 | B21: Tampering with Radar | C21: Radar | D21: =TRUE() -> TRUE | E21: Tampering
A22: TS-021 | B22: Repudiation of Radar actions | C22: Radar | D22: =FALSE() -> FALSE | E22: Repudiation
A23: TS-022 | B23: Information disclosure from Radar | C23: Radar | D23: =FALSE() -> FALSE | E23: Information Disclosure
A24: TS-023 | B24: Denial of service of Radar | C24: Radar | D24: =TRUE() -> TRUE | E24: Denial of Service
A25: TS-024 | B25: Elevation of privilege on Radar | C25: Radar | D25: =FALSE() -> FALSE | E25: Elevation of Privilege
A26: TS-025 | B26: Spoofing of LIDAR | C26: LIDAR | D26: =TRUE() -> TRUE | E26: Spoofing
A27: TS-026 | B27: Tampering with LIDAR | C27: LIDAR | D27: =TRUE() -> TRUE | E27: Tampering
A28: TS-027 | B28: Repudiation of LIDAR actions | C28: LIDAR | D28: =FALSE() -> FALSE | E28: Repudiation
A29: TS-028 | B29: Information disclosure from LIDAR | C29: LIDAR | D29: =FALSE() -> FALSE | E29: Information Disclosure
A30: TS-029 | B30: Denial of service of LIDAR | C30: LIDAR | D30: =TRUE() -> TRUE | E30: Denial of Service
A31: TS-030 | B31: Elevation of privilege on LIDAR | C31: LIDAR | D31: =FALSE() -> FALSE | E31: Elevation of Privilege
A32: TS-031 | B32: Spoofing of OBU | C32: OBU | D32: =TRUE() -> TRUE | E32: Spoofing
A33: TS-032 | B33: Tampering with OBU | C33: OBU | D33: =TRUE() -> TRUE | E33: Tampering
A34: TS-033 | B34: Repudiation of OBU actions | C34: OBU | D34: =TRUE() -> TRUE | E34: Repudiation
A35: TS-034 | B35: Information disclosure from OBU | C35: OBU | D35: =TRUE() -> TRUE | E35: Information Disclosure
A36: TS-035 | B36: Denial of service of OBU | C36: OBU | D36: =TRUE() -> TRUE | E36: Denial of Service
A37: TS-036 | B37: Elevation of privilege on OBU | C37: OBU | D37: =TRUE() -> TRUE | E37: Elevation of Privilege
A38: TS-037 | B38: Spoofing of Actuation Module | C38: Actuation Module | D38: =TRUE() -> TRUE | E38: Spoofing
A39: TS-038 | B39: Tampering with Actuation Module | C39: Actuation Module | D39: =TRUE() -> TRUE | E39: Tampering
A40: TS-039 | B40: Repudiation of Actuation Module actions | C40: Actuation Module | D40: =FALSE() -> FALSE | E40: Repudiation
...

Sheet Rationale
A1: ID | B1: Assets | C1: Element Type | D1: Category | E1: Security Property | F1: To Be Assessed | G1: Rationale
A2: TS-001 | B2: AI Controller Module | C2: Software Unit (Upper Level: Data Acquisition & Preprocessing + AI Decision Engine) | D2: Spoofing | E2: Authenticity | F2: =TRUE() -> TRUE | G2: An attacker node impersonates the AI Controller and sends forged speed/distance commands to the Actuation Module.
A3: TS-002 | B3: AI Controller Module | C3: Software Unit (Upper Level: Data Acquisition & Preprocessing + AI Decision Engine) | D3: Tampering | E3: Integrity | F3: =TRUE() -> TRUE | G3: Manipulation of the AI model (weights, poisoned training or update data) or of ACC parameters such as set speed and time gap, leading to unsafe decisions.
A4: TS-003 | B4: AI Controller Module | C4: Software Unit (Upper Level: Data Acquisition & Preprocessing + AI Decision Engine) | D4: Repudiation | E4: Non-repudiation | F4: =TRUE() -> TRUE | G4: Without secured logging of AI decisions and model updates, unsafe acceleration/braking or a malicious model update cannot be attributed or reconstructed after an incident.
A5: TS-004 | B5: AI Controller Module | C5: Software Unit (Upper Level: Data Acquisition & Preprocessing + AI Decision Engine) | D5: Information Disclosure | E5: Confidentiality | F5: =TRUE() -> TRUE | G5: Extraction of the AI model (model stealing or inversion) or of logged driving data through debug, diagnostic or update interfaces.
A6: TS-005 | B6: AI Controller Module | C6: Software Unit (Upper Level: Data Acquisition & Preprocessing + AI Decision Engine) | D6: Denial of Service | E6: Availability | F6: =TRUE() -> TRUE | G6: Resource exhaustion (inputs crafted to maximize inference latency, message flooding) delays or stops ACC decisions.
A7: TS-006 | B7: AI Controller Module | C7: Software Unit (Upper Level: Data Acquisition & Preprocessing + AI Decision Engine) | D7: Elevation of Privilege | E7: Authorization | F7: =TRUE() -> TRUE | G7: Exploiting a software vulnerability gives the attacker elevated rights (e.g., diagnostic or update functions) and full control over longitudinal decisions.
A8: TS-007 | B8: Perception Module | C8: Component (Lower Level) | D8: Spoofing | E8: Authenticity | F8: =TRUE() -> TRUE | G8: An attacker impersonates the Perception Module and feeds a fabricated environment model (fake or missing vehicles) to the AI Controller.
A9: TS-008 | B9: Perception Module | C9: Component (Lower Level) | D9: Tampering | E9: Integrity | F9: =TRUE() -> TRUE | G9: Modification of sensor fusion software, calibration or object tracking parameters causes wrong distance and relative speed estimates.
A10: TS-009 | B10: Perception Module | C10: Component (Lower Level) | D10: Repudiation | E10: Non-repudiation | F10: =FALSE() -> FALSE | G10: The module performs no user-initiated or accountable actions; traceability of decisions is assessed at the AI Controller Module.
A11: TS-010 | B11: Perception Module | C11: Component (Lower Level) | D11: Information Disclosure | E11: Confidentiality | F11: =TRUE() -> TRUE | G11: Access to fused sensor data (including camera-derived personal data) or reverse engineering of proprietary fusion algorithms.
A12: TS-011 | B12: Perception Module | C12: Component (Lower Level) | D12: Denial of Service | E12: Availability | F12: =TRUE() -> TRUE | G12: Overload or crash of the module (e.g., flooding its inputs) removes the environment model the ACC depends on.
A13: TS-012 | B13: Perception Module | C13: Component (Lower Level) | D13: Elevation of Privilege | E13: Authorization | F13: =TRUE() -> TRUE | G13: Exploiting a vulnerability in the perception software grants code execution and control over every object reported upstream.
A14: TS-013 | B14: Camera | C14: Sensor | D14: Spoofing | E14: Authenticity | F14: =TRUE() -> TRUE | G14: Adversarial or projected images (phantom vehicles, manipulated road markings) make the camera report non-existent or wrong objects.
A15: TS-014 | B15: Camera | C15: Sensor | D15: Tampering | E15: Integrity | F15: =TRUE() -> TRUE | G15: Physical tampering (misalignment, lens obstruction, recalibration) or firmware modification of the camera unit.
A16: TS-015 | B16: Camera | C16: Sensor | D16: Repudiation | E16: Non-repudiation | F16: =FALSE() -> FALSE | G16: A sensor performs no accountable actions and has no user identity; repudiation does not apply.
A17: TS-016 | B17: Camera | C17: Sensor | D17: Information Disclosure | E17: Confidentiality | F17: =FALSE() -> FALSE | G17: The camera does not store confidential data; disclosure of the image stream is assessed on data flow C Out → PM In.
A18: TS-017 | B18: Camera | C18: Sensor | D18: Denial of Service | E18: Availability | F18: =TRUE() -> TRUE | G18: Blinding with strong light or lasers, covering the lens or cutting power makes the camera unavailable.
A19: TS-018 | B19: Camera | C19: Sensor | D19: Elevation of Privilege | E19: Authorization | F19: =FALSE() -> FALSE | G19: Modeled as a sensor without a privileged software environment; there are no privilege levels to escalate.
A20: TS-019 | B20: Radar | C20: Sensor | D20: Spoofing | E20: Authenticity | F20: =TRUE() -> TRUE | G20: Radar spoofing or replay creates ghost targets or shifts the measured distance and relative speed of the lead vehicle.
A21: TS-020 | B21: Radar | C21: Sensor | D21: Tampering | E21: Integrity | F21: =TRUE() -> TRUE | G21: Physical misalignment or firmware/calibration manipulation distorts range and velocity measurements.
A22: TS-021 | B22: Radar | C22: Sensor | D22: Repudiation | E22: Non-repudiation | F22: =FALSE() -> FALSE | G22: A sensor performs no accountable actions and has no user identity; repudiation does not apply.
A23: TS-022 | B23: Radar | C23: Sensor | D23: Information Disclosure | E23: Confidentiality | F23: =FALSE() -> FALSE | G23: Radar returns contain no confidential or personal data.
A24: TS-023 | B24: Radar | C24: Sensor | D24: Denial of Service | E24: Availability | F24: =TRUE() -> TRUE | G24: Radar jamming or absorbing covers suppress detection of the lead vehicle.
A25: TS-024 | B25: Radar | C25: Sensor | D25: Elevation of Privilege | E25: Authorization | F25: =FALSE() -> FALSE | G25: Modeled as a sensor without a privileged software environment; there are no privilege levels to escalate.
A26: TS-025 | B26: LIDAR | C26: Sensor | D26: Spoofing | E26: Authenticity | F26: =TRUE() -> TRUE | G26: Injected laser pulses create fake points/objects or hide real obstacles.
A27: TS-026 | B27: LIDAR | C27: Sensor | D27: Tampering | E27: Integrity | F27: =TRUE() -> TRUE | G27: Physical tampering or manipulation of LIDAR firmware/calibration corrupts the point cloud.
A28: TS-027 | B28: LIDAR | C28: Sensor | D28: Repudiation | E28: Non-repudiation | F28: =FALSE() -> FALSE | G28: A sensor performs no accountable actions and has no user identity; repudiation does not apply.
A29: TS-028 | B29: LIDAR | C29: Sensor | D29: Information Disclosure | E29: Confidentiality | F29: =FALSE() -> FALSE | G29: Point clouds contain no confidential or personal data.
A30: TS-029 | B30: LIDAR | C30: Sensor | D30: Denial of Service | E30: Availability | F30: =TRUE() -> TRUE | G30: Saturating or blinding the receiver with laser light removes valid returns.
A31: TS-030 | B31: LIDAR | C31: Sensor | D31: Elevation of Privilege | E31: Authorization | F31: =FALSE() -> FALSE | G31: Modeled as a sensor without a privileged software environment; there are no privilege levels to escalate.
A32: TS-031 | B32: OBU | C32: Hardware Part (V2X On-Board Unit) | D32: Spoofing | E32: Authenticity | F32: =TRUE() -> TRUE | G32: Forged V2X messages (fake braking or position data from a non-existent vehicle, Sybil attack) or impersonation of the OBU with stolen credentials.
A33: TS-032 | B33: OBU | C33: Hardware Part (V2X On-Board Unit) | D33: Tampering | E33: Integrity | F33: =TRUE() -> TRUE | G33: Modification of OBU firmware or of received/transmitted V2X messages.
A34: TS-033 | B34: OBU | C34: Hardware Part (V2X On-Board Unit) | D34: Repudiation | E34: Non-repudiation | F34: =TRUE() -> TRUE | G34: A malicious V2X sender can deny having sent false messages if messages are not signed and logged; non-repudiation is needed for misbehavior reporting.
A35: TS-034 | B35: OBU | C35: Hardware Part (V2X On-Board Unit) | D35: Information Disclosure | E35: Confidentiality | F35: =TRUE() -> TRUE | G35: Extraction of V2X keys and certificates, or disclosure of vehicle identity and location history (privacy).
A36: TS-035 | B36: OBU | C36: Hardware Part (V2X On-Board Unit) | D36: Denial of Service | E36: Availability | F36: =TRUE() -> TRUE | G36: Radio jamming or flooding with V2X messages makes cooperative data unavailable.
A37: TS-036 | B37: OBU | C37: Hardware Part (V2X On-Board Unit) | D37: Elevation of Privilege | E37: Authorization | F37: =TRUE() -> TRUE | G37: The OBU is an external wireless entry point; a remotely exploitable vulnerability can give code execution and a pivot into the vehicle network.
A38: TS-037 | B38: Actuation Module | C38: Component (Lower Level) | D38: Spoofing | E38: Authenticity | F38: =TRUE() -> TRUE | G38: An attacker node impersonates the Actuation Module and sends forged commands directly to brake, throttle or AEB.
A39: TS-038 | B39: Actuation Module | C39: Component (Lower Level) | D39: Tampering | E39: Integrity | F39: =TRUE() -> TRUE | G39: Manipulation of actuation logic or limits (e.g., maximum deceleration or torque) so that decisions are applied incorrectly.
A40: TS-039 | B40: Actuation Module | C40: Component (Lower Level) | D40: Repudiation | E40: Non-repudiation | F40: =FALSE() -> FALSE | G40: The module executes commands from the AI Controller; accountability for those decisions is assessed at the AI Controller Module.
...

Sheet Summary
A1: Category | B1: Security Property | C1: To Be Assessed = TRUE | D1: To Be Assessed = FALSE | E1: Total
A2: Spoofing | B2: Authenticity | C2: =COUNTIFS(TARA!$E$2:$E$115,$A2,TARA!$D$2:$D$115,TRUE()) -> 7 | D2: =COUNTIFS(TARA!$E$2:$E$115,$A2,TARA!$D$2:$D$115,FALSE()) -> 12 | E2: =C2+D2 -> 19
A3: Tampering | B3: Integrity | C3: =COUNTIFS(TARA!$E$2:$E$115,$A3,TARA!$D$2:$D$115,TRUE()) -> 19 | D3: =COUNTIFS(TARA!$E$2:$E$115,$A3,TARA!$D$2:$D$115,FALSE()) -> 0 | E3: =C3+D3 -> 19
A4: Repudiation | B4: Non-repudiation | C4: =COUNTIFS(TARA!$E$2:$E$115,$A4,TARA!$D$2:$D$115,TRUE()) -> 2 | D4: =COUNTIFS(TARA!$E$2:$E$115,$A4,TARA!$D$2:$D$115,FALSE()) -> 17 | E4: =C4+D4 -> 19
A5: Information Disclosure | B5: Confidentiality | C5: =COUNTIFS(TARA!$E$2:$E$115,$A5,TARA!$D$2:$D$115,TRUE()) -> 5 | D5: =COUNTIFS(TARA!$E$2:$E$115,$A5,TARA!$D$2:$D$115,FALSE()) -> 14 | E5: =C5+D5 -> 19
A6: Denial of Service | B6: Availability | C6: =COUNTIFS(TARA!$E$2:$E$115,$A6,TARA!$D$2:$D$115,TRUE()) -> 19 | D6: =COUNTIFS(TARA!$E$2:$E$115,$A6,TARA!$D$2:$D$115,FALSE()) -> 0 | E6: =C6+D6 -> 19
A7: Elevation of Privilege | B7: Authorization | C7: =COUNTIFS(TARA!$E$2:$E$115,$A7,TARA!$D$2:$D$115,TRUE()) -> 4 | D7: =COUNTIFS(TARA!$E$2:$E$115,$A7,TARA!$D$2:$D$115,FALSE()) -> 15 | E7: =C7+D7 -> 19
A8: Total | C8: =SUM(C2:C7) -> 56 | D8: =SUM(D2:D7) -> 58 | E8: =SUM(E2:E7) -> 114
A10: Notes
A11: Method: STRIDE applied to every element and connector of the medini analyze architecture model (10 elements, 9 data flows, 6 categories each = 114 threat scenarios).
A12: STRIDE → security property mapping: Spoofing/Authenticity, Tampering/Integrity, Repudiation/Non-repudiation, Information Disclosure/Confidentiality, Denial of Service/Availability, Elevation of Privilege/Authorization.
A13: To Be Assessed = TRUE means the threat is relevant and goes on to risk assessment (impact and attack feasibility); FALSE means not applicable, with the reason on the Rationale sheet.
A14: Data flows follow STRIDE-per-element (Tampering, Information Disclosure, Denial of Service); spoofing on a flow is assessed on its sending element.
A15: Scope: only elements present in the medini model. The general architecture's direct Perception → Actuation path and the Continuous Vehicle Dynamics Monitoring Module loop are not modeled in medini and are excluded.
