Workbook

Sheet Threat Scenarios
A1: ID | B1: Name | C1: Assets | D1: To Be Assessed | E1: Category
A2: TS-001 | B2: Spoofing of AI Controller Module: a rogue ECU impersonates the AI controller and issues forged speed and distance decisions | C2: AI Controller Module | D2: =TRUE() -> TRUE | E2: Spoofing
A3: TS-002 | B3: Tampering with AI Controller Module: the AI model weights, firmware or decision logic are modified, e.g. a poisoned or backdoored model delivered through an update | C3: AI Controller Module | D3: =TRUE() -> TRUE | E3: Tampering
A4: TS-003 | B4: Repudiation of AI Controller Module: an unsafe ACC decision cannot be traced back to its inputs or to its source | C4: AI Controller Module | D4: =TRUE() -> TRUE | E4: Repudiation
A5: TS-004 | B5: Information Disclosure from AI Controller Module: the AI model or its parameters are extracted | C5: AI Controller Module | D5: =TRUE() -> TRUE | E5: Information Disclosure
A6: TS-005 | B6: Denial of Service against AI Controller Module: resource exhaustion or a crash stops the controller from producing ACC decisions | C6: AI Controller Module | D6: =TRUE() -> TRUE | E6: Denial of Service
A7: TS-006 | B7: Elevation of Privilege on AI Controller Module: an attacker gains privileged code execution on the controller (e.g. insecure update or debug access) and takes over its outputs | C7: AI Controller Module | D7: =TRUE() -> TRUE | E7: Elevation of Privilege
A8: TS-007 | B8: Spoofing of Perception Module: a rogue node impersonates the Perception Module and feeds a fabricated environment model to the AI controller | C8: Perception Module | D8: =TRUE() -> TRUE | E8: Spoofing
A9: TS-008 | B9: Tampering with Perception Module: the sensor fusion software or its calibration data is modified so object distance or speed is misreported | C9: Perception Module | D9: =TRUE() -> TRUE | E9: Tampering
A10: TS-009 | B10: Repudiation of Perception Module | C10: Perception Module | D10: =FALSE() -> FALSE | E10: Repudiation
A11: TS-010 | B11: Information Disclosure from Perception Module: fused environment data, including camera imagery and vehicle position, is leaked | C11: Perception Module | D11: =TRUE() -> TRUE | E11: Information Disclosure
A12: TS-011 | B12: Denial of Service against Perception Module: the fusion pipeline is overloaded (e.g. flooded with sensor frames) and object output is delayed or stopped | C12: Perception Module | D12: =TRUE() -> TRUE | E12: Denial of Service
A13: TS-012 | B13: Elevation of Privilege on Perception Module: code execution on the Perception Module is used as a pivot toward the AI controller and the vehicle network | C13: Perception Module | D13: =TRUE() -> TRUE | E13: Elevation of Privilege
A14: TS-013 | B14: Spoofing of Camera: adversarial patches, projected images or screens create phantom vehicles or hide real ones | C14: Camera | D14: =TRUE() -> TRUE | E14: Spoofing
A15: TS-014 | B15: Tampering with Camera: the camera is misaligned, its lens obstructed or its firmware modified so the captured scene is altered | C15: Camera | D15: =TRUE() -> TRUE | E15: Tampering
A16: TS-015 | B16: Repudiation of Camera | C16: Camera | D16: =FALSE() -> FALSE | E16: Repudiation
A17: TS-016 | B17: Information Disclosure from Camera: camera imagery is exposed through a compromised camera or its debug access | C17: Camera | D17: =TRUE() -> TRUE | E17: Information Disclosure
A18: TS-017 | B18: Denial of Service against Camera: the camera is blinded with strong light or a laser, or covered, and visual perception is lost | C18: Camera | D18: =TRUE() -> TRUE | E18: Denial of Service
A19: TS-018 | B19: Elevation of Privilege on Camera | C19: Camera | D19: =FALSE() -> FALSE | E19: Elevation of Privilege
A20: TS-019 | B20: Spoofing of Radar: a radar signal generator injects ghost targets with false distance or relative speed | C20: Radar | D20: =TRUE() -> TRUE | E20: Spoofing
A21: TS-020 | B21: Tampering with Radar: the radar mounting is misaligned or its firmware changed so measurements are distorted | C21: Radar | D21: =TRUE() -> TRUE | E21: Tampering
A22: TS-021 | B22: Repudiation of Radar | C22: Radar | D22: =FALSE() -> FALSE | E22: Repudiation
A23: TS-022 | B23: Information Disclosure from Radar | C23: Radar | D23: =FALSE() -> FALSE | E23: Information Disclosure
A24: TS-023 | B24: Denial of Service against Radar: radar jamming or interference masks real targets | C24: Radar | D24: =TRUE() -> TRUE | E24: Denial of Service
A25: TS-024 | B25: Elevation of Privilege on Radar | C25: Radar | D25: =FALSE() -> FALSE | E25: Elevation of Privilege
A26: TS-025 | B26: Spoofing of LIDAR: injected laser pulses create spoofed points and fake obstacles | C26: LIDAR | D26: =TRUE() -> TRUE | E26: Spoofing
A27: TS-026 | B27: Tampering with LIDAR: the LIDAR calibration, mounting or firmware is changed so the point cloud is distorted | C27: LIDAR | D27: =TRUE() -> TRUE | E27: Tampering
A28: TS-027 | B28: Repudiation of LIDAR | C28: LIDAR | D28: =FALSE() -> FALSE | E28: Repudiation
A29: TS-028 | B29: Information Disclosure from LIDAR | C29: LIDAR | D29: =FALSE() -> FALSE | E29: Information Disclosure
A30: TS-029 | B30: Denial of Service against LIDAR: laser saturation or jamming removes valid returns | C30: LIDAR | D30: =TRUE() -> TRUE | E30: Denial of Service
A31: TS-030 | B31: Elevation of Privilege on LIDAR | C31: LIDAR | D31: =FALSE() -> FALSE | E31: Elevation of Privilege
A32: TS-031 | B32: Spoofing of OBU: forged V2X messages (fake vehicles, fake braking warnings) are accepted as genuine | C32: OBU | D32: =TRUE() -> TRUE | E32: Spoofing
A33: TS-032 | B33: Tampering with OBU: the OBU firmware or the V2X content it forwards is modified | C33: OBU | D33: =TRUE() -> TRUE | E33: Tampering
A34: TS-033 | B34: Repudiation of OBU: a sender denies having transmitted a V2X message because messages are not verifiably signed | C34: OBU | D34: =TRUE() -> TRUE | E34: Repudiation
A35: TS-034 | B35: Information Disclosure from OBU: vehicle position, trajectory or V2X credentials are leaked, enabling tracking | C35: OBU | D35: =TRUE() -> TRUE | E35: Information Disclosure
A36: TS-035 | B36: Denial of Service against OBU: RF jamming or message flooding blocks V2X reception | C36: OBU | D36: =TRUE() -> TRUE | E36: Denial of Service
A37: TS-036 | B37: Elevation of Privilege on OBU: remote code execution through the wireless interface gives a foothold in the vehicle network | C37: OBU | D37: =TRUE() -> TRUE | E37: Elevation of Privilege
A38: TS-037 | B38: Spoofing of Actuation Module: a rogue ECU impersonates the Actuation Module and issues brake and throttle commands | C38: Actuation Module | D38: =TRUE() -> TRUE | E38: Spoofing
A39: TS-038 | B39: Tampering with Actuation Module: the actuation logic, command limits or command translation is modified | C39: Actuation Module | D39: =TRUE() -> TRUE | E39: Tampering
A40: TS-039 | B40: Repudiation of Actuation Module | C40: Actuation Module | D40: =FALSE() -> FALSE | E40: Repudiation
...

Sheet Rationale
A1: ID | B1: Assets | C1: Asset Type | D1: Category | E1: To Be Assessed | F1: Rationale
A2: TS-001 | B2: AI Controller Module | C2: Software Unit (upper level) | D2: Spoofing | E2: =TRUE() -> TRUE | F2: The controller's output directly commands longitudinal motion, so the receivers must be able to trust where decisions come from.
A3: TS-002 | B3: AI Controller Module | C3: Software Unit (upper level) | D3: Tampering | E3: =TRUE() -> TRUE | F3: Loss of integrity in the decision engine leads straight to unsafe acceleration or braking.
A4: TS-003 | B4: AI Controller Module | C4: Software Unit (upper level) | D4: Repudiation | E4: =TRUE() -> TRUE | F4: AI decisions need a trustworthy log for accident investigation and liability; injected decisions would otherwise go unattributed.
A5: TS-004 | B5: AI Controller Module | C5: Software Unit (upper level) | D5: Information Disclosure | E5: =TRUE() -> TRUE | F5: Protects intellectual property, and a leaked model enables white-box adversarial attacks on the perception inputs.
A6: TS-005 | B6: AI Controller Module | C6: Software Unit (upper level) | D6: Denial of Service | E6: =TRUE() -> TRUE | F6: Losing decisions while driving at speed is safety relevant.
A7: TS-006 | B7: AI Controller Module | C7: Software Unit (upper level) | D7: Elevation of Privilege | E7: =TRUE() -> TRUE | F7: Highest-impact case: full control of longitudinal vehicle control.
A8: TS-007 | B8: Perception Module | C8: Component (lower level) | D8: Spoofing | E8: =TRUE() -> TRUE | F8: The AI controller trusts the object list completely; a fake source can steer every decision.
A9: TS-008 | B9: Perception Module | C9: Component (lower level) | D9: Tampering | E9: =TRUE() -> TRUE | F9: Wrong fused data produces wrong decisions without any sensor being attacked.
A10: TS-009 | B10: Perception Module | C10: Component (lower level) | D10: Repudiation | E10: =FALSE() -> FALSE | F10: The module produces data, not attributable actions; traceability of decisions is handled at the AI Controller.
A11: TS-010 | B11: Perception Module | C11: Component (lower level) | D11: Information Disclosure | E11: =TRUE() -> TRUE | F11: Holds personal data (bystanders, plates, location), which is relevant under data protection rules.
A12: TS-011 | B12: Perception Module | C12: Component (lower level) | D12: Denial of Service | E12: =TRUE() -> TRUE | F12: Late or missing perception data leaves the AI controller blind.
A13: TS-012 | B13: Perception Module | C13: Component (lower level) | D13: Elevation of Privilege | E13: =TRUE() -> TRUE | F13: It is a software component with network connections, so a compromise can spread.
A14: TS-013 | B14: Camera | C14: Sensor | D14: Spoofing | E14: =TRUE() -> TRUE | F14: A known attack class against AI-based vision; it needs no access to the vehicle.
A15: TS-014 | B15: Camera | C15: Sensor | D15: Tampering | E15: =TRUE() -> TRUE | F15: Changes what the perception chain sees at the source.
A16: TS-015 | B16: Camera | C16: Sensor | D16: Repudiation | E16: =FALSE() -> FALSE | F16: A fixed-function sensor performs no actions that need attribution.
A17: TS-016 | B17: Camera | C17: Sensor | D17: Information Disclosure | E17: =TRUE() -> TRUE | F17: Video contains personal data about bystanders, plates and routes.
A18: TS-017 | B18: Camera | C18: Sensor | D18: Denial of Service | E18: =TRUE() -> TRUE | F18: Easy to perform and removes a primary input.
A19: TS-018 | B19: Camera | C19: Sensor | D19: Elevation of Privilege | E19: =FALSE() -> FALSE | F19: A fixed-function sensor has no privilege model to escalate within.
A20: TS-019 | B20: Radar | C20: Sensor | D20: Spoofing | E20: =TRUE() -> TRUE | F20: Directly affects the distance-keeping function ACC depends on.
A21: TS-020 | B21: Radar | C21: Sensor | D21: Tampering | E21: =TRUE() -> TRUE | F21: Biased range or angle readings shift every following decision.
A22: TS-021 | B22: Radar | C22: Sensor | D22: Repudiation | E22: =FALSE() -> FALSE | F22: A fixed-function sensor performs no actions that need attribution.
A23: TS-022 | B23: Radar | C23: Sensor | D23: Information Disclosure | E23: =FALSE() -> FALSE | F23: Radar returns carry no confidential or personal information of value.
A24: TS-023 | B24: Radar | C24: Sensor | D24: Denial of Service | E24: =TRUE() -> TRUE | F24: Loss of the main ranging sensor for ACC.
A25: TS-024 | B25: Radar | C25: Sensor | D25: Elevation of Privilege | E25: =FALSE() -> FALSE | F25: A fixed-function sensor has no privilege model to escalate within.
A26: TS-025 | B26: LIDAR | C26: Sensor | D26: Spoofing | E26: =TRUE() -> TRUE | F26: Demonstrated attack class; can trigger phantom braking.
A27: TS-026 | B27: LIDAR | C27: Sensor | D27: Tampering | E27: =TRUE() -> TRUE | F27: Corrupts 3D object detection at the source.
A28: TS-027 | B28: LIDAR | C28: Sensor | D28: Repudiation | E28: =FALSE() -> FALSE | F28: A fixed-function sensor performs no actions that need attribution.
A29: TS-028 | B29: LIDAR | C29: Sensor | D29: Information Disclosure | E29: =FALSE() -> FALSE | F29: Raw point clouds carry little confidential value.
A30: TS-029 | B30: LIDAR | C30: Sensor | D30: Denial of Service | E30: =TRUE() -> TRUE | F30: Loss of a ranging input.
A31: TS-030 | B31: LIDAR | C31: Sensor | D31: Elevation of Privilege | E31: =FALSE() -> FALSE | F31: A fixed-function sensor has no privilege model to escalate within.
A32: TS-031 | B32: OBU | C32: Hardware Part (V2X on-board unit) | D32: Spoofing | E32: =TRUE() -> TRUE | F32: Remote attack that needs no physical access; V2X data feeds perception directly.
A33: TS-032 | B33: OBU | C33: Hardware Part (V2X on-board unit) | D33: Tampering | E33: =TRUE() -> TRUE | F33: A compromised OBU can alter what the rest of the system believes about traffic ahead.
A34: TS-033 | B34: OBU | C34: Hardware Part (V2X on-board unit) | D34: Repudiation | E34: =TRUE() -> TRUE | F34: V2X relies on signed messages for attribution and misbehaviour reporting.
A35: TS-034 | B35: OBU | C35: Hardware Part (V2X on-board unit) | D35: Information Disclosure | E35: =TRUE() -> TRUE | F35: Location privacy and credential protection.
A36: TS-035 | B36: OBU | C36: Hardware Part (V2X on-board unit) | D36: Denial of Service | E36: =TRUE() -> TRUE | F36: Removes cooperative information and can overload processing.
A37: TS-036 | B37: OBU | C37: Hardware Part (V2X on-board unit) | D37: Elevation of Privilege | E37: =TRUE() -> TRUE | F37: The OBU is the only externally reachable interface in the model, so it is the main remote entry point.
A38: TS-037 | B38: Actuation Module | C38: Component (lower level) | D38: Spoofing | E38: =TRUE() -> TRUE | F38: Actuators trust this module as the only command source.
A39: TS-038 | B39: Actuation Module | C39: Component (lower level) | D39: Tampering | E39: =TRUE() -> TRUE | F39: Could remove safety limits on acceleration or deceleration.
A40: TS-039 | B40: Actuation Module | C40: Component (lower level) | D40: Repudiation | E40: =FALSE() -> FALSE | F40: Executes commands decided upstream; attribution is handled at the AI Controller.
...

Sheet Summary
A1: TARA of AI-based ACC - AI engine run (STRIDE)
A3: STRIDE category | B3: Security property | C3: To Be Assessed = TRUE | D3: FALSE | E3: Total
A4: Spoofing | B4: Authenticity | C4: =COUNTIFS('Threat Scenarios'!$E$2:$E$115,A4,'Threat Scenarios'!$D$2:$D$115,TRUE()) -> 16 | D4: =COUNTIFS('Threat Scenarios'!$E$2:$E$115,A4,'Threat Scenarios'!$D$2:$D$115,FALSE()) -> 3 | E4: =C4+D4 -> 19
A5: Tampering | B5: Integrity | C5: =COUNTIFS('Threat Scenarios'!$E$2:$E$115,A5,'Threat Scenarios'!$D$2:$D$115,TRUE()) -> 19 | D5: =COUNTIFS('Threat Scenarios'!$E$2:$E$115,A5,'Threat Scenarios'!$D$2:$D$115,FALSE()) -> 0 | E5: =C5+D5 -> 19
A6: Repudiation | B6: Non-repudiation | C6: =COUNTIFS('Threat Scenarios'!$E$2:$E$115,A6,'Threat Scenarios'!$D$2:$D$115,TRUE()) -> 3 | D6: =COUNTIFS('Threat Scenarios'!$E$2:$E$115,A6,'Threat Scenarios'!$D$2:$D$115,FALSE()) -> 16 | E6: =C6+D6 -> 19
A7: Information Disclosure | B7: Confidentiality | C7: =COUNTIFS('Threat Scenarios'!$E$2:$E$115,A7,'Threat Scenarios'!$D$2:$D$115,TRUE()) -> 8 | D7: =COUNTIFS('Threat Scenarios'!$E$2:$E$115,A7,'Threat Scenarios'!$D$2:$D$115,FALSE()) -> 11 | E7: =C7+D7 -> 19
A8: Denial of Service | B8: Availability | C8: =COUNTIFS('Threat Scenarios'!$E$2:$E$115,A8,'Threat Scenarios'!$D$2:$D$115,TRUE()) -> 19 | D8: =COUNTIFS('Threat Scenarios'!$E$2:$E$115,A8,'Threat Scenarios'!$D$2:$D$115,FALSE()) -> 0 | E8: =C8+D8 -> 19
A9: Elevation of Privilege | B9: Authorization | C9: =COUNTIFS('Threat Scenarios'!$E$2:$E$115,A9,'Threat Scenarios'!$D$2:$D$115,TRUE()) -> 4 | D9: =COUNTIFS('Threat Scenarios'!$E$2:$E$115,A9,'Threat Scenarios'!$D$2:$D$115,FALSE()) -> 15 | E9: =C9+D9 -> 19
A10: Total | C10: =SUM(C4:C9) -> 69 | D10: =SUM(D4:D9) -> 45 | E10: =SUM(E4:E9) -> 114
A12: Asset | B12: Asset type | C12: To Be Assessed = TRUE | D12: Total
A13: AI Controller Module | B13: Software Unit (upper level) | C13: =COUNTIFS('Threat Scenarios'!$C$2:$C$115,A13,'Threat Scenarios'!$D$2:$D$115,TRUE()) -> 6 | D13: =COUNTIF('Threat Scenarios'!$C$2:$C$115,A13) -> 6
A14: Perception Module | B14: Component (lower level) | C14: =COUNTIFS('Threat Scenarios'!$C$2:$C$115,A14,'Threat Scenarios'!$D$2:$D$115,TRUE()) -> 5 | D14: =COUNTIF('Threat Scenarios'!$C$2:$C$115,A14) -> 6
A15: Camera | B15: Sensor | C15: =COUNTIFS('Threat Scenarios'!$C$2:$C$115,A15,'Threat Scenarios'!$D$2:$D$115,TRUE()) -> 4 | D15: =COUNTIF('Threat Scenarios'!$C$2:$C$115,A15) -> 6
A16: Radar | B16: Sensor | C16: =COUNTIFS('Threat Scenarios'!$C$2:$C$115,A16,'Threat Scenarios'!$D$2:$D$115,TRUE()) -> 3 | D16: =COUNTIF('Threat Scenarios'!$C$2:$C$115,A16) -> 6
A17: LIDAR | B17: Sensor | C17: =COUNTIFS('Threat Scenarios'!$C$2:$C$115,A17,'Threat Scenarios'!$D$2:$D$115,TRUE()) -> 3 | D17: =COUNTIF('Threat Scenarios'!$C$2:$C$115,A17) -> 6
A18: OBU | B18: Hardware Part (V2X on-board unit) | C18: =COUNTIFS('Threat Scenarios'!$C$2:$C$115,A18,'Threat Scenarios'!$D$2:$D$115,TRUE()) -> 6 | D18: =COUNTIF('Threat Scenarios'!$C$2:$C$115,A18) -> 6
A19: Actuation Module | B19: Component (lower level) | C19: =COUNTIFS('Threat Scenarios'!$C$2:$C$115,A19,'Threat Scenarios'!$D$2:$D$115,TRUE()) -> 4 | D19: =COUNTIF('Threat Scenarios'!$C$2:$C$115,A19) -> 6
A20: Brake | B20: Actuator | C20: =COUNTIFS('Threat Scenarios'!$C$2:$C$115,A20,'Threat Scenarios'!$D$2:$D$115,TRUE()) -> 2 | D20: =COUNTIF('Threat Scenarios'!$C$2:$C$115,A20) -> 6
A21: Throttle | B21: Actuator | C21: =COUNTIFS('Threat Scenarios'!$C$2:$C$115,A21,'Threat Scenarios'!$D$2:$D$115,TRUE()) -> 2 | D21: =COUNTIF('Threat Scenarios'!$C$2:$C$115,A21) -> 6
A22: AEB | B22: Hardware Part | C22: =COUNTIFS('Threat Scenarios'!$C$2:$C$115,A22,'Threat Scenarios'!$D$2:$D$115,TRUE()) -> 3 | D22: =COUNTIF('Threat Scenarios'!$C$2:$C$115,A22) -> 6
A23: PM Out → AI In | B23: Connection (perception data to AI controller) | C23: =COUNTIFS('Threat Scenarios'!$C$2:$C$115,A23,'Threat Scenarios'!$D$2:$D$115,TRUE()) -> 4 | D23: =COUNTIF('Threat Scenarios'!$C$2:$C$115,A23) -> 6
A24: AI Out → AM In | B24: Connection (decisions to actuation) | C24: =COUNTIFS('Threat Scenarios'!$C$2:$C$115,A24,'Threat Scenarios'!$D$2:$D$115,TRUE()) -> 4 | D24: =COUNTIF('Threat Scenarios'!$C$2:$C$115,A24) -> 6
... A31: AM Out → AEB In | B31: Connection (AEB trigger) | C31: =COUNTIFS('Threat Scenarios'!$C$2:$C$115,A31,'Threat Scenarios'!$D$2:$D$115,TRUE()) -> 3 | D31: =COUNTIF('Threat Scenarios'!$C$2:$C$115,A31) -> 6
A33: Method notes
A34: Scope: the elements of the medini analyze model (10 components, sensors, actuators and hardware parts, plus the 9 connections between them), so each row can be matched 1:1 with the medini output.
A35: Every asset gets one row per STRIDE category. To Be Assessed = TRUE means the threat is credible for that element and should go on to impact and attack feasibility rating; FALSE means it does not apply (reason on the Rationale sheet).
A36: STRIDE to security property: Spoofing - Authenticity, Tampering - Integrity, Repudiation - Non-repudiation, Information Disclosure - Confidentiality, Denial of Service - Availability, Elevation of Privilege - Authorization.
A37: Applicability rule used: processing components can face all six categories; fixed-function sensors and actuators have no privilege model (no Elevation of Privilege) and perform no attributable actions (no Repudiation); connections are assessed for Spoofing, Tampering, Information Disclosure and Denial of Service. Deliberate exceptions: the OBU gets all six because it is the external wireless entry point, and AEB keeps Repudiation because emergency braking events must be provable afterwards.
A38: Not modelled in medini, so kept out of this table: the Continuous Vehicle Dynamics Monitoring Module and its feedback loop, and the direct Perception to Actuation link shown in the general architecture.
A39: IDs (TS-001 ...) are this run's own numbering. Match rows to medini by Assets + Category.
