Workbook

Sheet TARA
A1: ID | B1: Name | C1: Assets | D1: To Be Assessed | E1: Category
A2: TS-001 | B2: Impersonation of AI Controller Module issuing fake driving decisions | C2: AI Controller Module | D2: =TRUE() -> TRUE | E2: Spoofing
A3: TS-002 | B3: Tampering with AI model, parameters or software of AI Controller Module | C3: AI Controller Module | D3: =TRUE() -> TRUE | E3: Tampering
A4: TS-003 | B4: Repudiation of AI driving decisions due to missing tamper-proof logging | C4: AI Controller Module | D4: =TRUE() -> TRUE | E4: Repudiation
A5: TS-004 | B5: Extraction of AI model and disclosure of driving data from AI Controller Module | C5: AI Controller Module | D5: =TRUE() -> TRUE | E5: Information Disclosure
A6: TS-005 | B6: Denial of service of AI Controller Module | C6: AI Controller Module | D6: =TRUE() -> TRUE | E6: Denial of Service
A7: TS-006 | B7: Elevation of privilege on AI Controller Module | C7: AI Controller Module | D7: =TRUE() -> TRUE | E7: Elevation of Privilege
A8: TS-007 | B8: Impersonation of Perception Module sending a fake environment model | C8: Perception Module | D8: =TRUE() -> TRUE | E8: Spoofing
A9: TS-008 | B9: Tampering with sensor fusion software or calibration of Perception Module | C9: Perception Module | D9: =TRUE() -> TRUE | E9: Tampering
A10: TS-009 | B10: Repudiation of perception outputs | C10: Perception Module | D10: =FALSE() -> FALSE | E10: Repudiation
A11: TS-010 | B11: Disclosure of fused sensor data from Perception Module | C11: Perception Module | D11: =TRUE() -> TRUE | E11: Information Disclosure
A12: TS-011 | B12: Denial of service of Perception Module | C12: Perception Module | D12: =TRUE() -> TRUE | E12: Denial of Service
A13: TS-012 | B13: Elevation of privilege on Perception Module | C13: Perception Module | D13: =TRUE() -> TRUE | E13: Elevation of Privilege
A14: TS-013 | B14: Impersonation of Actuation Module towards the actuators | C14: Actuation Module | D14: =TRUE() -> TRUE | E14: Spoofing
A15: TS-014 | B15: Tampering with control logic of Actuation Module | C15: Actuation Module | D15: =TRUE() -> TRUE | E15: Tampering
A16: TS-015 | B16: Repudiation of actuation commands | C16: Actuation Module | D16: =FALSE() -> FALSE | E16: Repudiation
A17: TS-016 | B17: Disclosure of actuation data from Actuation Module | C17: Actuation Module | D17: =FALSE() -> FALSE | E17: Information Disclosure
A18: TS-017 | B18: Denial of service of Actuation Module | C18: Actuation Module | D18: =TRUE() -> TRUE | E18: Denial of Service
A19: TS-018 | B19: Elevation of privilege on Actuation Module | C19: Actuation Module | D19: =TRUE() -> TRUE | E19: Elevation of Privilege
A20: TS-019 | B20: Camera spoofing via adversarial patterns or projected objects | C20: Camera | D20: =TRUE() -> TRUE | E20: Spoofing
A21: TS-020 | B21: Physical or firmware tampering with Camera | C21: Camera | D21: =TRUE() -> TRUE | E21: Tampering
A22: TS-021 | B22: Repudiation of camera data | C22: Camera | D22: =FALSE() -> FALSE | E22: Repudiation
A23: TS-022 | B23: Disclosure of camera images | C23: Camera | D23: =TRUE() -> TRUE | E23: Information Disclosure
A24: TS-023 | B24: Camera blinding or dazzling | C24: Camera | D24: =TRUE() -> TRUE | E24: Denial of Service
A25: TS-024 | B25: Elevation of privilege on Camera | C25: Camera | D25: =FALSE() -> FALSE | E25: Elevation of Privilege
A26: TS-025 | B26: Radar spoofing with fake echoes (ghost targets) | C26: Radar | D26: =TRUE() -> TRUE | E26: Spoofing
A27: TS-026 | B27: Physical or firmware tampering with Radar | C27: Radar | D27: =TRUE() -> TRUE | E27: Tampering
A28: TS-027 | B28: Repudiation of radar data | C28: Radar | D28: =FALSE() -> FALSE | E28: Repudiation
A29: TS-028 | B29: Disclosure of radar detections | C29: Radar | D29: =FALSE() -> FALSE | E29: Information Disclosure
A30: TS-029 | B30: Radar jamming | C30: Radar | D30: =TRUE() -> TRUE | E30: Denial of Service
A31: TS-030 | B31: Elevation of privilege on Radar | C31: Radar | D31: =FALSE() -> FALSE | E31: Elevation of Privilege
A32: TS-031 | B32: LIDAR spoofing via injected laser pulses | C32: LIDAR | D32: =TRUE() -> TRUE | E32: Spoofing
A33: TS-032 | B33: Physical or firmware tampering with LIDAR | C33: LIDAR | D33: =TRUE() -> TRUE | E33: Tampering
A34: TS-033 | B34: Repudiation of LIDAR data | C34: LIDAR | D34: =FALSE() -> FALSE | E34: Repudiation
A35: TS-034 | B35: Disclosure of LIDAR point clouds | C35: LIDAR | D35: =FALSE() -> FALSE | E35: Information Disclosure
A36: TS-035 | B36: LIDAR saturation or jamming | C36: LIDAR | D36: =TRUE() -> TRUE | E36: Denial of Service
A37: TS-036 | B37: Elevation of privilege on LIDAR | C37: LIDAR | D37: =FALSE() -> FALSE | E37: Elevation of Privilege
A38: TS-037 | B38: Spoofing of V2X messages received by OBU | C38: OBU | D38: =TRUE() -> TRUE | E38: Spoofing
A39: TS-038 | B39: Tampering with OBU firmware or V2X messages | C39: OBU | D39: =TRUE() -> TRUE | E39: Tampering
A40: TS-039 | B40: Repudiation of V2X messages | C40: OBU | D40: =TRUE() -> TRUE | E40: Repudiation
...

Sheet Details
A1: ID | B1: Assets | C1: Category | D1: Cybersecurity Property | E1: Threat Description | F1: To Be Assessed | G1: Rationale
A2: TS-001 | B2: =INDEX(TARA!$C$2:$C$115,MATCH(A2,TARA!$A$2:$A$115,0)) -> AI Controller Module | C2: =INDEX(TARA!$E$2:$E$115,MATCH(A2,TARA!$A$2:$A$115,0)) -> Spoofing | D2: Authenticity | E2: A compromised or rogue ECU impersonates the AI Controller Module and sends acceleration or deceleration requests to the Actuation Module, which accepts them because the sender is not authenticated. | F2: =INDEX(TARA!$D$2:$D$115,MATCH(A2,TARA!$A$2:$A$115,0)) -> TRUE | G2: The Actuation Module relies on the identity of the AI controller; spoofed decisions directly affect longitudinal control (safety impact).
A3: TS-002 | B3: =INDEX(TARA!$C$2:$C$115,MATCH(A3,TARA!$A$2:$A$115,0)) -> AI Controller Module | C3: =INDEX(TARA!$E$2:$E$115,MATCH(A3,TARA!$A$2:$A$115,0)) -> Tampering | D3: Integrity | E3: The attacker modifies model weights, inserts a backdoor, poisons training or update data, or changes ACC parameters (set speed, time gap, acceleration limits) through a malicious update or diagnostic access, causing unsafe decisions. | F3: =INDEX(TARA!$D$2:$D$115,MATCH(A3,TARA!$A$2:$A$115,0)) -> TRUE | G3: Integrity of the decision logic is the core of the ACC function; manipulation leads to unintended acceleration or missed braking.
A4: TS-003 | B4: =INDEX(TARA!$C$2:$C$115,MATCH(A4,TARA!$A$2:$A$115,0)) -> AI Controller Module | C4: =INDEX(TARA!$E$2:$E$115,MATCH(A4,TARA!$A$2:$A$115,0)) -> Repudiation | D4: Non-repudiation | E4: Decisions of the AI Decision Engine and changes to its parameters or model are not logged in a protected way, so an unsafe decision or a malicious change cannot be traced or proven after an incident. | F4: =INDEX(TARA!$D$2:$D$115,MATCH(A4,TARA!$A$2:$A$115,0)) -> TRUE | G4: Traceability of AI decisions is needed for incident analysis, liability and forensic evidence of attacks on an AI-based function.
A5: TS-004 | B5: =INDEX(TARA!$C$2:$C$115,MATCH(A5,TARA!$A$2:$A$115,0)) -> AI Controller Module | C5: =INDEX(TARA!$E$2:$E$115,MATCH(A5,TARA!$A$2:$A$115,0)) -> Information Disclosure | D5: Confidentiality | E5: The attacker reads the model (weights, architecture) via debug interfaces or memory dumps, reconstructs it by repeated querying (model extraction or inversion), or accesses stored driving data. | F5: =INDEX(TARA!$D$2:$D$115,MATCH(A5,TARA!$A$2:$A$115,0)) -> TRUE | G5: The model is valuable IP, an extracted model enables targeted adversarial examples, and stored data may reveal personal driving behavior.
A6: TS-005 | B6: =INDEX(TARA!$C$2:$C$115,MATCH(A6,TARA!$A$2:$A$115,0)) -> AI Controller Module | C6: =INDEX(TARA!$E$2:$E$115,MATCH(A6,TARA!$A$2:$A$115,0)) -> Denial of Service | D6: Availability | E6: Resource exhaustion (flooded inputs, crafted inputs that cause worst-case inference time, triggered crash or watchdog reset) prevents the AI controller from producing decisions in real time. | F6: =INDEX(TARA!$D$2:$D$115,MATCH(A6,TARA!$A$2:$A$115,0)) -> TRUE | G6: Missing or late decisions degrade or disable ACC while the vehicle is moving.
A7: TS-006 | B7: =INDEX(TARA!$C$2:$C$115,MATCH(A7,TARA!$A$2:$A$115,0)) -> AI Controller Module | C7: =INDEX(TARA!$E$2:$E$115,MATCH(A7,TARA!$A$2:$A$115,0)) -> Elevation of Privilege | D7: Authorization | E7: Exploitation of a software vulnerability, weak diagnostic authentication (e.g. UDS security access) or an open debug port gives privileged execution, allowing reprogramming or disabling of safety limits. | F7: =INDEX(TARA!$D$2:$D$115,MATCH(A7,TARA!$A$2:$A$115,0)) -> TRUE | G7: Privileged access on the decision unit enables all other attacks on longitudinal control.
A8: TS-007 | B8: =INDEX(TARA!$C$2:$C$115,MATCH(A8,TARA!$A$2:$A$115,0)) -> Perception Module | C8: =INDEX(TARA!$E$2:$E$115,MATCH(A8,TARA!$A$2:$A$115,0)) -> Spoofing | D8: Authenticity | E8: An attacker node pretends to be the Perception Module and sends a fabricated object list (e.g. no lead vehicle, or a phantom obstacle) to the AI Controller Module. | F8: =INDEX(TARA!$D$2:$D$115,MATCH(A8,TARA!$A$2:$A$115,0)) -> TRUE | G8: The AI controller trusts perception output; spoofing causes unintended acceleration or phantom braking.
A9: TS-008 | B9: =INDEX(TARA!$C$2:$C$115,MATCH(A9,TARA!$A$2:$A$115,0)) -> Perception Module | C9: =INDEX(TARA!$E$2:$E$115,MATCH(A9,TARA!$A$2:$A$115,0)) -> Tampering | D9: Integrity | E9: Manipulation of fusion algorithms, object filtering thresholds or sensor calibration data (range offset, mounting angles) so that distance and relative speed of the lead vehicle are computed wrongly. | F9: =INDEX(TARA!$D$2:$D$115,MATCH(A9,TARA!$A$2:$A$115,0)) -> TRUE | G9: Wrong distance or relative speed estimates directly lead to an unsafe following distance.
A10: TS-009 | B10: =INDEX(TARA!$C$2:$C$115,MATCH(A10,TARA!$A$2:$A$115,0)) -> Perception Module | C10: =INDEX(TARA!$E$2:$E$115,MATCH(A10,TARA!$A$2:$A$115,0)) -> Repudiation | D10: Non-repudiation | E10: The Perception Module denies having produced a specific object list. | F10: =INDEX(TARA!$D$2:$D$115,MATCH(A10,TARA!$A$2:$A$115,0)) -> FALSE | G10: The Perception Module performs no accountable actions of its own; decision traceability is covered by TS-003.
A11: TS-010 | B11: =INDEX(TARA!$C$2:$C$115,MATCH(A11,TARA!$A$2:$A$115,0)) -> Perception Module | C11: =INDEX(TARA!$E$2:$E$115,MATCH(A11,TARA!$A$2:$A$115,0)) -> Information Disclosure | D11: Confidentiality | E11: The attacker reads fused environment data including camera images and V2X position data, revealing persons, license plates and vehicle location, or the fusion algorithm IP. | F11: =INDEX(TARA!$D$2:$D$115,MATCH(A11,TARA!$A$2:$A$115,0)) -> TRUE | G11: The data contains personal and location data, so confidentiality is relevant (privacy impact).
A12: TS-011 | B12: =INDEX(TARA!$C$2:$C$115,MATCH(A12,TARA!$A$2:$A$115,0)) -> Perception Module | C12: =INDEX(TARA!$E$2:$E$115,MATCH(A12,TARA!$A$2:$A$115,0)) -> Denial of Service | D12: Availability | E12: Overloading the module with input (e.g. flooded point clouds or V2X messages) or triggering a crash so that no environment model is delivered in time. | F12: =INDEX(TARA!$D$2:$D$115,MATCH(A12,TARA!$A$2:$A$115,0)) -> TRUE | G12: Without perception output ACC cannot keep a safe distance.
A13: TS-012 | B13: =INDEX(TARA!$C$2:$C$115,MATCH(A13,TARA!$A$2:$A$115,0)) -> Perception Module | C13: =INDEX(TARA!$E$2:$E$115,MATCH(A13,TARA!$A$2:$A$115,0)) -> Elevation of Privilege | D13: Authorization | E13: Exploiting a parser vulnerability (e.g. in V2X message or sensor frame handling) to execute code with elevated privileges and pivot to the AI Controller Module. | F13: =INDEX(TARA!$D$2:$D$115,MATCH(A13,TARA!$A$2:$A$115,0)) -> TRUE | G13: The module processes externally influenced data (OBU, sensors), which makes it a likely entry point for code execution.
... A115: TS-114 | B115: =INDEX(TARA!$C$2:$C$115,MATCH(A115,TARA!$A$2:$A$115,0)) -> Actuation Module → AEB (AM Out → AEB In) | C115: =INDEX(TARA!$E$2:$E$115,MATCH(A115,TARA!$A$2:$A$115,0)) -> Elevation of Privilege | D115: Authorization | E115: Privilege escalation through the link. | F115: =INDEX(TARA!$D$2:$D$115,MATCH(A115,TARA!$A$2:$A$115,0)) -> FALSE | G115: A data flow does not execute code or hold privileges; elevation of privilege is not applicable.

Sheet Assets
A1: Asset | B1: Element Type (medini) | C1: Architecture Level | D1: Threat Scenarios | E1: To Be Assessed = TRUE | F1: To Be Assessed = FALSE
A2: AI Controller Module | B2: Software Unit | C2: Upper level (Data Acquisition & Preprocessing + AI Decision Engine) | D2: =COUNTIF(TARA!$C$2:$C$115,A2) -> 6 | E2: =COUNTIFS(TARA!$C$2:$C$115,A2,TARA!$D$2:$D$115,TRUE()) -> 6 | F2: =COUNTIFS(TARA!$C$2:$C$115,A2,TARA!$D$2:$D$115,FALSE()) -> 0
A3: Perception Module | B3: Component | C3: Lower level | D3: =COUNTIF(TARA!$C$2:$C$115,A3) -> 6 | E3: =COUNTIFS(TARA!$C$2:$C$115,A3,TARA!$D$2:$D$115,TRUE()) -> 5 | F3: =COUNTIFS(TARA!$C$2:$C$115,A3,TARA!$D$2:$D$115,FALSE()) -> 1
A4: Actuation Module | B4: Component | C4: Lower level | D4: =COUNTIF(TARA!$C$2:$C$115,A4) -> 6 | E4: =COUNTIFS(TARA!$C$2:$C$115,A4,TARA!$D$2:$D$115,TRUE()) -> 4 | F4: =COUNTIFS(TARA!$C$2:$C$115,A4,TARA!$D$2:$D$115,FALSE()) -> 2
A5: Camera | B5: Sensor | C5: Lower level (Perception) | D5: =COUNTIF(TARA!$C$2:$C$115,A5) -> 6 | E5: =COUNTIFS(TARA!$C$2:$C$115,A5,TARA!$D$2:$D$115,TRUE()) -> 4 | F5: =COUNTIFS(TARA!$C$2:$C$115,A5,TARA!$D$2:$D$115,FALSE()) -> 2
A6: Radar | B6: Sensor | C6: Lower level (Perception) | D6: =COUNTIF(TARA!$C$2:$C$115,A6) -> 6 | E6: =COUNTIFS(TARA!$C$2:$C$115,A6,TARA!$D$2:$D$115,TRUE()) -> 3 | F6: =COUNTIFS(TARA!$C$2:$C$115,A6,TARA!$D$2:$D$115,FALSE()) -> 3
A7: LIDAR | B7: Sensor | C7: Lower level (Perception) | D7: =COUNTIF(TARA!$C$2:$C$115,A7) -> 6 | E7: =COUNTIFS(TARA!$C$2:$C$115,A7,TARA!$D$2:$D$115,TRUE()) -> 3 | F7: =COUNTIFS(TARA!$C$2:$C$115,A7,TARA!$D$2:$D$115,FALSE()) -> 3
A8: OBU | B8: Hardware Part | C8: Lower level (Perception) | D8: =COUNTIF(TARA!$C$2:$C$115,A8) -> 6 | E8: =COUNTIFS(TARA!$C$2:$C$115,A8,TARA!$D$2:$D$115,TRUE()) -> 6 | F8: =COUNTIFS(TARA!$C$2:$C$115,A8,TARA!$D$2:$D$115,FALSE()) -> 0
A9: Brake | B9: Actuator | C9: Lower level (Actuation) | D9: =COUNTIF(TARA!$C$2:$C$115,A9) -> 6 | E9: =COUNTIFS(TARA!$C$2:$C$115,A9,TARA!$D$2:$D$115,TRUE()) -> 2 | F9: =COUNTIFS(TARA!$C$2:$C$115,A9,TARA!$D$2:$D$115,FALSE()) -> 4
A10: Throttle | B10: Actuator | C10: Lower level (Actuation) | D10: =COUNTIF(TARA!$C$2:$C$115,A10) -> 6 | E10: =COUNTIFS(TARA!$C$2:$C$115,A10,TARA!$D$2:$D$115,TRUE()) -> 2 | F10: =COUNTIFS(TARA!$C$2:$C$115,A10,TARA!$D$2:$D$115,FALSE()) -> 4
A11: AEB | B11: Hardware Part | C11: Lower level (Actuation) | D11: =COUNTIF(TARA!$C$2:$C$115,A11) -> 6 | E11: =COUNTIFS(TARA!$C$2:$C$115,A11,TARA!$D$2:$D$115,TRUE()) -> 2 | F11: =COUNTIFS(TARA!$C$2:$C$115,A11,TARA!$D$2:$D$115,FALSE()) -> 4
A12: Camera → Perception Module (C Out → PM In) | B12: Interface (data flow) | C12: Lower level | D12: =COUNTIF(TARA!$C$2:$C$115,A12) -> 6 | E12: =COUNTIFS(TARA!$C$2:$C$115,A12,TARA!$D$2:$D$115,TRUE()) -> 4 | F12: =COUNTIFS(TARA!$C$2:$C$115,A12,TARA!$D$2:$D$115,FALSE()) -> 2
A13: Radar → Perception Module (R Out → PM In) | B13: Interface (data flow) | C13: Lower level | D13: =COUNTIF(TARA!$C$2:$C$115,A13) -> 6 | E13: =COUNTIFS(TARA!$C$2:$C$115,A13,TARA!$D$2:$D$115,TRUE()) -> 3 | F13: =COUNTIFS(TARA!$C$2:$C$115,A13,TARA!$D$2:$D$115,FALSE()) -> 3
... A20: Actuation Module → AEB (AM Out → AEB In) | B20: Interface (data flow) | C20: Lower level | D20: =COUNTIF(TARA!$C$2:$C$115,A20) -> 6 | E20: =COUNTIFS(TARA!$C$2:$C$115,A20,TARA!$D$2:$D$115,TRUE()) -> 3 | F20: =COUNTIFS(TARA!$C$2:$C$115,A20,TARA!$D$2:$D$115,FALSE()) -> 3
A21: Total | D21: =SUM(D2:D20) -> 114 | E21: =SUM(E2:E20) -> 66 | F21: =SUM(F2:F20) -> 48

Sheet Summary
A1: STRIDE Category | B1: Cybersecurity Property | C1: Threat Scenarios | D1: To Be Assessed = TRUE | E1: To Be Assessed = FALSE
A2: Spoofing | B2: Authenticity | C2: =COUNTIF(TARA!$E$2:$E$115,A2) -> 19 | D2: =COUNTIFS(TARA!$E$2:$E$115,A2,TARA!$D$2:$D$115,TRUE()) -> 16 | E2: =COUNTIFS(TARA!$E$2:$E$115,A2,TARA!$D$2:$D$115,FALSE()) -> 3
A3: Tampering | B3: Integrity | C3: =COUNTIF(TARA!$E$2:$E$115,A3) -> 19 | D3: =COUNTIFS(TARA!$E$2:$E$115,A3,TARA!$D$2:$D$115,TRUE()) -> 19 | E3: =COUNTIFS(TARA!$E$2:$E$115,A3,TARA!$D$2:$D$115,FALSE()) -> 0
A4: Repudiation | B4: Non-repudiation | C4: =COUNTIF(TARA!$E$2:$E$115,A4) -> 19 | D4: =COUNTIFS(TARA!$E$2:$E$115,A4,TARA!$D$2:$D$115,TRUE()) -> 2 | E4: =COUNTIFS(TARA!$E$2:$E$115,A4,TARA!$D$2:$D$115,FALSE()) -> 17
A5: Information Disclosure | B5: Confidentiality | C5: =COUNTIF(TARA!$E$2:$E$115,A5) -> 19 | D5: =COUNTIFS(TARA!$E$2:$E$115,A5,TARA!$D$2:$D$115,TRUE()) -> 6 | E5: =COUNTIFS(TARA!$E$2:$E$115,A5,TARA!$D$2:$D$115,FALSE()) -> 13
A6: Denial of Service | B6: Availability | C6: =COUNTIF(TARA!$E$2:$E$115,A6) -> 19 | D6: =COUNTIFS(TARA!$E$2:$E$115,A6,TARA!$D$2:$D$115,TRUE()) -> 19 | E6: =COUNTIFS(TARA!$E$2:$E$115,A6,TARA!$D$2:$D$115,FALSE()) -> 0
A7: Elevation of Privilege | B7: Authorization | C7: =COUNTIF(TARA!$E$2:$E$115,A7) -> 19 | D7: =COUNTIFS(TARA!$E$2:$E$115,A7,TARA!$D$2:$D$115,TRUE()) -> 4 | E7: =COUNTIFS(TARA!$E$2:$E$115,A7,TARA!$D$2:$D$115,FALSE()) -> 15
A8: Total | C8: =SUM(C2:C7) -> 114 | D8: =SUM(D2:D7) -> 66 | E8: =SUM(E2:E7) -> 48
A10: Method notes
A11: Threat scenarios generated by the AI engine by applying all six STRIDE categories to every asset of the medini architecture model.
A12: Assets: the 10 architecture elements (AI Controller Module, Perception Module, Actuation Module, Camera, Radar, LIDAR, OBU, Brake, Throttle, AEB) and the 9 port connections between them.
A13: STRIDE to property mapping (ISO/SAE 21434): Spoofing - Authenticity, Tampering - Integrity, Repudiation - Non-repudiation, Information Disclosure - Confidentiality, Denial of Service - Availability, Elevation of Privilege - Authorization.
A14: To Be Assessed = FALSE marks a threat judged not applicable or already covered by another scenario; the reason is in the Details sheet.
A15: The Continuous Vehicle Dynamics Monitoring Module from the general architecture is not part of the medini model and is not included.
A16: Source of the architecture: user-provided diagrams (general architecture and medini architecture).
